Workbook

Sheet تسعير
A1: رايزني فرهنگي جمهوري اسلامي ايران در : ترکمنستان | I1: رايزني فرهنگي جمهوري اسلامي ايران در : ترکمنستان
A2: از تاريخ 92/1/1 لغايت 92/11/30 | I2: از تاريخ 92/1/1 لغايت 92/11/30
A4: رديف | B4: تاريخ | C4: شماره چك/نقدي | D4: مبلغ يورو | E4: نرخ تسعير | F4: تبديلي به: منات | G4: ملاحضات | I4: ردیف | J4: تاریخ | K4: یورو | L4: تسعیر دلار | M4: تبدیل شده به دلار | N4: تسعیر منات | O4: تبدیل شده به منات
A5: 1 | E5: =F5/D5 -> #DIV/0! | I5: 1 | K5: 8943.18 | L5: =M5/K5 -> 1.3200003 | M5: 11805 | N5: =O5/M5 -> 2.86 | O5: 33762.3
A6: 2 | B6: طول مدت | C6: آزاد | D6: 5452.66 | E6: =F6/D6 -> 3.7750016 | F6: 20583.8 | G6: بدون رسید و یا فیش | I6: 2
A7: 3 | C7: آزاد | D7: 10000 | E7: =F7/D7 -> 3.775 | F7: 37750 | G7: بدون رسید و یا فیش | I7: 3
A8: 4 | C8: آزاد | D8: 10000 | E8: =F8/D8 -> 3.775 | F8: 37750 | G8: بدون رسید و یا فیش | I8: 4
A9: 5 | C9: آزاد | D9: 10000 | E9: =F9/D9 -> 3.775 | F9: 37750 | G9: بدون رسید و یا فیش | I9: 5
A10: 6 | C10: آزاد | D10: 10000 | E10: =F10/D10 -> 3.775 | F10: 37750 | G10: بدون رسید و یا فیش | I10: 6
A11: 7 | C11: آزاد | D11: 10000 | E11: =F11/D11 -> 3.775 | F11: 37750 | G11: بدون رسید و یا فیش | I11: 7
A12: 8 | C12: آزاد | G12: بدون رسید و یا فیش | I12: 8
A13: 9 | C13: آزاد | G13: بدون رسید و یا فیش | I13: 9
A14: 10 | C14: آزاد | G14: بدون رسید و یا فیش | I14: 10
A15: 11 | C15: آزاد | G15: بدون رسید و یا فیش | I15: 11
A16: 12 | I16: 12
A17: 13 | I17: 13
A18: 14 | I18: 14
A19: 15 | E19: =F19/D19 -> #DIV/0! | I19: 15 | L19: =M19/K19 -> #DIV/0!
A20: 16 | E20: =F20/D20 -> #DIV/0! | I20: 16 | L20: =M20/K20 -> #DIV/0! | N20: =O20/M20 -> #DIV/0!
A21: 17 | E21: =F21/D21 -> #DIV/0! | I21: 17 | L21: =M21/K21 -> #DIV/0! | N21: =O21/M21 -> #DIV/0!
A22: 18 | E22: =F22/D22 -> #DIV/0! | I22: 18 | L22: =M22/K22 -> #DIV/0! | N22: =O22/M22 -> #DIV/0!
A23: 19 | E23: =F23/D23 -> #DIV/0! | I23: 19 | L23: =M23/K23 -> #DIV/0! | N23: =O23/M23 -> #DIV/0!
A24: 20 | E24: =F24/D24 -> #DIV/0! | I24: 20 | L24: =M24/K24 -> #DIV/0! | N24: =O24/M24 -> #DIV/0!
A25: 21 | E25: =F25/D25 -> #DIV/0! | I25: 21 | L25: =M25/K25 -> #DIV/0! | N25: =O25/M25 -> #DIV/0!
A26: 22 | E26: =F26/D26 -> #DIV/0! | I26: 22 | L26: =M26/K26 -> #DIV/0! | N26: =O26/M26 -> #DIV/0!
A27: 23 | E27: =F27/D27 -> #DIV/0! | I27: 23 | L27: =M27/K27 -> #DIV/0! | N27: =O27/M27 -> #DIV/0!
A28: 24 | E28: =F28/D28 -> #DIV/0! | I28: 24 | L28: =M28/K28 -> #DIV/0! | N28: =O28/M28 -> #DIV/0!
A29: 25 | E29: =F29/D29 -> #DIV/0! | I29: 25 | L29: =M29/K29 -> #DIV/0! | N29: =O29/M29 -> #DIV/0!
A30: 26 | E30: =F30/D30 -> #DIV/0! | I30: 26 | L30: =M30/K30 -> #DIV/0! | N30: =O30/M30 -> #DIV/0!
A31: 27 | E31: =F31/D31 -> #DIV/0! | I31: 27 | L31: =M31/K31 -> #DIV/0! | N31: =O31/M31 -> #DIV/0!
... A33: 29 | E33: =F33/D33 -> #DIV/0! | I33: 29 | L33: =M33/K33 -> #DIV/0! | N33: =O33/M33 -> #DIV/0!
A34: جمع كل | D34: =SUM(D5:D33) -> 55452.66 | E34: =F34/D34 -> 3.7750002 | F34: =SUM(F5:F33) -> 209333.8 | I34: جمع کل | K34: =SUM(K5:K33) -> 8943.18 | L34: =M34/K34 -> 1.3200003 | M34: =SUM(M5:M33) -> 11805 | N34: =O34/M34 -> 2.86 | O34: =SUM(O5:O33) -> 33762.3
A35: مصرف اين دوره حسب فهرست هزينه ها: | F35: ='روكش جاري و فرهنگي'!D81+'روكش جاري و فرهنگي'!D35 -> 209333.8 | K35: 18681.52/4948=3.755 رقم تسعیر منات به یورو
A36: مانده موجودي قابل انتقال به دوره بعد: | D36: =F36/E36 -> 0 | E36: =F34/D34 -> 3.7750002 | F36: =F34-F35 -> 0
A38: تنظيم كننده: | D38: حسابرس اعزامي: | E38: سعید حقانی | F38: رايزني فرهنگي ج .ا.ا: آقای اسماعیل زاده | I38: تنظيم كننده: | L38: حسابرس اعزامي: | M38: سعید حقانی | N38: رايزن فرهنگي ج .ا.ا: آقای اسماعیل زاده
A41: رايزني فرهنگي جمهوري اسلامي ايران در : ترکمنستان
A42: از تاريخ 92/1/1 لغايت 92/11/30
A44: رديف | B44: تاريخ | C44: شماره چك/نقدي | D44: مبلغ يورو | E44: نرخ تسعير | F44: تبديلي به: دلار | G44: ملاحضات
A45: 1 | D45: 8943.18 | E45: =F45/D45 -> 1.3200003 | F45: 11805
A46: 2
...

Sheet ريز جاري
A1: رايزني فرهنگي ج.ا.ايران در:ترکمنستان | J1: هزينه بانكي(كارمزد)
A2: سال 1392/1/1 لغایت 92/11/30 | F2: کد: | J2: حقوق،بازخريدي و...كاركنان بومي
A3: هزينه جاري:بانكي(كارمزد) | F3: نرخ تسعير: | G3: =تسعير!E34 -> 3.7750002 | J3: خريد اقلام مصرفي و پذیرائی
A4: رديف | B4: تارخ سند | C4: شرح | D4: سند | E4: ارز محل | F4: معادل به يورو | G4: يورو | H4: جمع به يورو | J4: هزينه آب برق گاز و ساير سوخت ها
A5: 1 | F5: =E5/G3 -> 0 | H5: =G5+F5 -> 0 | J5: تعمير و نگهداري خودرو
A6: 2 | F6: =E6/G3 -> 0 | H6: =G6+F6 -> 0 | J6: ترميم و نگهداري جزئي ساختمان
A7: 3 | F7: =E7/G3 -> 0 | H7: =G7+F7 -> 0 | J7: حمل و نقل و ارتباطات
A8: 4 | F8: =E8/G3 -> 0 | H8: =G8+F8 -> 0 | J8: تلفن،فاكس و اينترنت
A9: 5 | F9: =E9/G3 -> 0 | H9: =G9+F9 -> 0 | J9: کمک هزینه تحصیلی فرزندان
A10: 6 | F10: =E10/G3 -> 0 | H10: =G10+F10 -> 0 | J10: كمك هزينه درمان و بيمه كاركنان
A11: 7 | F11: =E11/G3 -> 0 | H11: =G11+F11 -> 0 | J11: هزينه هاي خارج از مصوب و تخصيص
A12: 8 | F12: =E12/G3 -> 0 | H12: =G12+F12 -> 0 | J12: هزينه هاي پيش بيني نشده
A13: 9 | F13: =E13/G3 -> 0 | H13: =G13+F13 -> 0
A14: 10 | F14: =E14/G3 -> 0 | H14: =G14+F14 -> 0
A15: 11 | F15: =E15/G3 -> 0 | H15: =G15+F15 -> 0
A16: 12 | F16: =E16/G3 -> 0 | H16: =G16+F16 -> 0
A17: 13 | F17: =E17/G3 -> 0 | H17: =G17+F17 -> 0
A18: 14 | F18: =E18/G3 -> 0 | H18: =G18+F18 -> 0
A19: 15 | F19: =E19/G3 -> 0 | H19: =G19+F19 -> 0
A20: 16 | F20: =E20/G3 -> 0 | H20: =G20+F20 -> 0
A21: 17 | F21: =E21/G3 -> 0 | H21: =G21+F21 -> 0
A22: 18 | F22: =E22/G3 -> 0 | H22: =G22+F22 -> 0
A23: 19 | F23: =E23/G3 -> 0 | H23: =G23+F23 -> 0
A24: 20 | F24: =E24/G3 -> 0 | H24: =G24+F24 -> 0
A25: 21 | F25: =E25/G3 -> 0 | H25: =G25+F25 -> 0
A26: 22 | F26: =E26/G3 -> 0 | H26: =G26+F26 -> 0
A27: 23 | F27: =E27/G3 -> 0 | H27: =G27+F27 -> 0
A28: 24 | F28: =E28/G3 -> 0 | H28: =G28+F28 -> 0
A29: 25 | F29: =E29/G3 -> 0 | H29: =G29+F29 -> 0
A30: جمع كل | E30: =SUM(E5:E29) -> 0 | F30: =E30/G3 -> 0 | G30: =SUM(G5:G29) -> 0 | H30: =SUM(H5:H29) -> 0
A32: تنظيم كننده: | C32: حسابرس اعزامي: سعید حقانی | E32: رايزن فرهنگي: آقای اسماعیل زاده
A43: رايزني فرهنگي ج.ا.ايران در::ترکمنستان | F43: کد: 921321412
A44: سال 1392/1/1 لغایت 92/11/30 | F44: کد:921321413
A45: هزينه جاري:حقوق، بازخريدي و...كاركنان بومي | F45: نرخ تسعير: | G45: =تسعير!E34 -> 3.7750002
A46: رديف | B46: تارخ سند | C46: شرح | D46: سند | E46: ارز محل | F46: معادل به يورو | G46: يورو | H46: جمع به يورو
A47: 1 | B47: 92/1/30 | C47: حقوق کارکنان در فروردین | F47: =E47/G3 -> 0 | G47: 1621 | H47: =G47+F47 -> 1621
A48: 2 | B48: 92/2/30 | C48: حقوق کارکنان در اردیبهشت | F48: =E48/G3 -> 0 | G48: 1371 | H48: =G48+F48 -> 1371
A49: 3 | B49: 92/3/30 | C49: حقوق کارکنان در خرداد | F49: =E49/G3 -> 0 | G49: 1371 | H49: =G49+F49 -> 1371
A50: 4 | B50: 92/4/30 | C50: حقوق کارکنان در تیر | F50: =E50/G3 -> 0 | G50: 1621 | H50: =G50+F50 -> 1621
A51: 5 | B51: 92/5/30 | C51: اضافه کار سه ماهه اول سال | F51: =E51/G3 -> 0 | G51: 257.5 | H51: =G51+F51 -> 257.5
...

Sheet ريز فرهنگي
A1: رايزني فرهنگي ج.ا.ايران در:ترکمنستان | J1: هزينه يك:برگزاري جشن نوروز
A2: سال 1392/1/1 لغایت 92/11/30 | F2: کد: 9213214114 | J2: هزينه دو:انتشار 4 شماره از نشريه دوره اي خاوران
A3: هزينه فرهنگي يك: برگزاري جشن نوروز | F3: نرخ تسعير: | G3: =تسعير!E34 -> 3.7750002 | J3: هزينه سه: تعمیر و تجهیز مساجد
A4: رديف | B4: تارخ سند | C4: شرح | D4: سند | E4: ارز محل | F4: معادل به يورو | G4: يورو | H4: جمع به يورو | J4: هزينه چهار:برگزاری همایش امام رضاع
A5: 1 | B5: 92/1/3 | C5: حق الزحمه ودود موذن زاده | F5: =E5/G3 -> 0 | G5: 500 | H5: =G5+F5 -> 500 | J5: هزينه فرهنگي پنج: اجرای برنامه های مبادلات فرهنگی
A6: 2 | B6: 92/1/2 | C6: حق الزحمه سقلی | F6: =E6/G3 -> 0 | G6: 150 | H6: =G6+F6 -> 150 | J6: هزينه شش:ترجمه وانتشار نهج البلاغه
A7: 3 | B7: 91/12/28 | C7: چاپ بنر کتاب نوروز | E7: 35 | F7: =E7/G3 -> 9.2715228 | H7: =G7+F7 -> 9.2715228 | J7: هزينه هفت:حمايت از فعاليتهاي ديني وتبليغي
A8: 4 | B8: 91/12/30 | C8: غذای راننده ها در جشن نوروز | E8: 49 | F8: =E8/G3 -> 12.980132 | H8: =G8+F8 -> 12.980132 | J8: هزینه هشت: ترجمه و چاپ کتاب آموزش زبان فارسی اول به ترکمنی
A9: 5 | B9: 91/12/29 | C9: غذای راننده ها در جشن نوروز | E9: 58 | F9: =E9/G3 -> 15.364238 | H9: =G9+F9 -> 15.364238 | J9: هزينه نه:برگزاري 4 دوره (ترم) آموزش زبان فارسي
A10: 6 | B10: 91/12/29 | C10: شارژ تلفن راننده ها در جشن نوروز | E10: 330 | F10: =E10/G3 -> 87.417215 | H10: =G10+F10 -> 87.417215 | J10: هزينه ده:برگزاري مراسم و مناسبت هاي ديني و مذهبي
A11: 7 | B11: 92/1/5 | C11: کارگر بار کامیون کانون | E11: 150 | F11: =E11/G3 -> 39.735098 | H11: =G11+F11 -> 39.735098 | J11: هزینه 11: برگزاری مراسم ارتحال سالگرد امام ره
A12: 8 | B12: 91/12/23 | C12: خرید آلاچیق | E12: 3809 | F12: =E12/G3 -> 1009.0066 | H12: =G12+F12 -> 1009.0066 | J12: هزینه 12: برگزاری مراسم نیمه شعبان
A13: 9 | B13: 91/12/29 | C13: هزینه شارژ تلفن همکاران | E13: 150 | F13: =E13/G3 -> 39.735098 | H13: =G13+F13 -> 39.735098 | J13: هزینه 13:ترجمه و انتشار کتاب ادعیه و سوره ها همراه با آونگاری آذری
A14: 10 | B14: 91/12/29 | C14: هزینه شارژ تلفن همکاران | E14: 100 | F14: =E14/G3 -> 26.490065 | H14: =G14+F14 -> 26.490065 | J14: هزینه 14:تجهیز اتاق ایران
A15: 11 | B15: 91/12/29 | C15: هزینه شارژ تلفن همکاران | E15: 80 | F15: =E15/G3 -> 21.192052 | H15: =G15+F15 -> 21.192052 | J15: هزینه:15 برگزاری 3 اردوی علمی آموزشی فارسی آموزان
A16: 12 | B16: 91/12/29 | C16: تهیه و تنظیم مدارک ترخیص بار کامیون | E16: 1000 | F16: =E16/G3 -> 264.90065 | H16: =G16+F16 -> 264.90065 | J16: هزینه16: ترجمه چاپ نامه امام علی ع به مالک به زبان ترکمنی
A17: 13 | B17: 92/1/19 | C17: تعمیر و سرویس کامپیوتر | E17: 60 | F17: =E17/G3 -> 15.894039 | H17: =G17+F17 -> 15.894039 | J17: هزینه17: چاپ کتاب صحیفه سجادیه به زبان ترکمنی
A18: 14 | B18: 91/12/25 | C18: طراحی بنر رونمایی کتاب | E18: 60 | F18: =E18/G3 -> 15.894039 | H18: =G18+F18 -> 15.894039 | J18: هزینه18: ترجمه قرآن به زبان ترکمنی
A19: 15 | B19: 91/12/28 | C19: ترجمه و ویرایش نوروزنامه(اتایف | E19: 1200 | F19: =E19/G3 -> 317.88078 | H19: =G19+F19 -> 317.88078
A20: 16 | B20: 92/2/12 | C20: طراحی جلد کتاب نوروز نامه(دلار | E20: 343.2 | F20: =E20/G3 -> 90.913904 | H20: =G20+F20 -> 90.913904
A21: 17 | B21: 92/1/5 | C21: 120ضرب2.86تسعیر=343.2منات | F21: =E21/G3 -> 0 | H21: =G21+F21 -> 0
A22: 18 | B22: 91/12/29 | C22: تهیه و تنظیم مدارک ترخیص بار کامیون(دلار | E22: 1001 | F22: =E22/G3 -> 265.16555 | H22: =G22+F22 -> 265.16555
A23: 19 | C23: 350ضرب2.86تسعیر=1001منات | F23: =E23/G3 -> 0 | H23: =G23+F23 -> 0
A24: 20 | C24: حق الزحمه همکاری در برگزاری جشن نوروز (دلار | E24: 429 | F24: =E24/G3 -> 113.64238 | H24: =G24+F24 -> 113.64238
A25: 21 | C25: 150ضرب2.86تسعیر=429منات | F25: =E25/G3 -> 0 | H25: =G25+F25 -> 0
A26: 22 | D26: 31 | F26: =E26/G3 -> 0 | H26: =G26+F26 -> 0
A27: 23 | F27: =E27/G3 -> 0 | H27: =G27+F27 -> 0
A28: 24 | F28: =E28/G3 -> 0 | H28: =G28+F28 -> 0
A29: 25 | C29: جمع سند | D29: =SUM(D5:D28) -> 31 | F29: =E29/G3 -> 0 | H29: =G29+F29 -> 0
A30: جمع كل | E30: =SUM(E5:E29) -> 8854.2 | F30: =E30/G3 -> 2345.4833 | G30: =SUM(G5:G29) -> 650 | H30: =SUM(H5:H29) -> 2995.4833
A32: تنظيم كننده: | C32: حسابرس اعزامي: | E32: رايزن فرهنگي:
A43: رايزني فرهنگي ج.ا.ايران در:ترکمنستان
A44: سال 1392/1/1 لغایت 92/11/30 | F44: کد: 9213214117
A45: هزينه فرهنگي دو: انتشار 4 شماره از نشريه دوره اي خاوران | F45: نرخ تسعير: | G45: =تسعير!E34 -> 3.7750002
A46: رديف | B46: تارخ سند | C46: شرح | D46: سند | E46: ارز محل | F46: معادل به يورو | G46: يورو | H46: جمع به يورو
A47: 1 | B47: 92/1/20 | C47: ترجمه مستندات محل اقامت امام رضاع مجله 39-38 | E47: 100 | F47: =E47/G3 -> 26.490065 | H47: =G47+F47 -> 26.490065
A48: 2 | B48: 92/6/1 | C48: ترجمه مقالات مجله خاوران 39-38 | E48: 425 | F48: =E48/G3 -> 112.58278 | H48: =G48+F48 -> 112.58278
A49: 3 | B49: 92/5/15 | C49: ترجمه مقالات مجله 39-38 | E49: 3315 | F49: =E49/G3 -> 878.14566 | H49: =G49+F49 -> 878.14566
A50: 4 | B50: 92/11/23 | C50: چاپ رنگی سی دی مجله 39-38 | E50: 540 | F50: =E50/G3 -> 143.04635 | H50: =G50+F50 -> 143.04635
A51: 5 | C51: طراحی مجله 39-38 | E51: 1760 | F51: =E51/G3 -> 466.22515 | H51: =G51+F51 -> 466.22515
...

Sheet حقوق مرکزی ها
A1: هزینه حقوق: پرسنلی اعزامی از مرکز
A2: نمایندگی ج.ا.ایران در ترکمنستان
A3: سال 1392/1/1 لغایت 92/12/29 | G3: ارقام : یورو
A5: ردیف | B5: نام و نام خانوادگی | C5: رسول اسماعیل زاده | D5: نعمتی زاده | E5: اضافه کار نعمتی زاده | F5: میرمحمدی | H5: توضیحات
A6: 1 | B6: فروردین | F6: 8898
A7: 2 | B7: اردیبهشت | F7: 2966
A8: 3 | B8: خرداد | C8: 14082 | D8: 7800
A9: 4 | B9: تیر
A10: 5 | B10: مرداد | D10: 5200
A11: 6 | B11: شهریور | D11: 2600
A12: 7 | B12: مهر
A13: 8 | B13: آبان
A14: 9 | B14: آذر | D14: 7800
A15: 10 | B15: دی | D15: 2600
A16: 11 | B16: بهمن | D16: 2417
A17: 12 | B17: اسفند
A18: جمع پرداخت شده به تفکیک افراد | C18: =SUM(C6:C17) -> 14082 | D18: =SUM(D6:D17) -> 28417 | E18: =SUM(E6:E17) -> 0 | F18: =SUM(F6:F17) -> 11864 | G18: =SUM(G6:G17) -> 0
A19: جمع کل : | C19: =G18+F18+E18+D18+C18 -> 54363
B22: تنظیم کننده : سعید حقانی | F22: رایزنی فرهنگی ج.ا.ایران در ترکمنستان :
F23: رسول اسماعیل زاده

Sheet روكش جاري و فرهنگي
A1: ليست كلي هزينه هاي جاري رايزني فرهنگي ج.ا.ايران در ترکمنستان -عشق آباد
A2: سال 1392/1/1 لغایت 92/11/30
D3: نرخ تسعیر: | E3: =تسعير!E34 -> 3.7750002
A4: رديف | B4: كد برنامه | C4: عنوان برنامه | D4: ارز محل | E4: يورو | F4: جمع به يورو
A5: 1 | C5: هزينه بانكي | D5: ='ريز جاري'!E30 -> 0 | E5: ='ريز جاري'!G30 -> 0 | F5: =D5/تسعير!E34+E5 -> 0
A6: 2 | B6: 921321412 921321413 | C6: هزينه:حقوق، بازخريدي و...كاركنان بومي | D6: ='ريز جاري'!E72 -> 0 | E6: ='ريز جاري'!G72 -> 19591 | F6: =D6/تسعير!E34+E6 -> 19591
A7: 3 | B7: 9213214156 | C7: هزينه:هزينه آب برق گاز و ساير سوخت ها | D7: ='ريز جاري'!E156 -> 2109 | E7: ='ريز جاري'!G156 -> 0 | F7: =D7/تسعير!E34+E7 -> 558.67547
A8: 4 | B8: 9213214155 | C8: هزينه:تعمير و نگهداري خودرو | D8: ='ريز جاري'!E198 -> 3535.5 | E8: ='ريز جاري'!G198 -> 0 | F8: =D8/تسعير!E34+E8 -> 936.55625
A9: 5 | B9: 9213214154 | C9: ترميم و نگهداري جزئي ساختمان | D9: ='ريز جاري'!E240 -> 1384 | E9: ='ريز جاري'!G240 -> 0 | F9: =D9/تسعير!E34+E9 -> 366.6225
A10: 6 | B10: 9213214160 | C10: حمل و نقل و ارتباطات | D10: ='ريز جاري'!E282 -> 3823 | E10: ='ريز جاري'!G282 -> 0 | F10: =D10/تسعير!E34+E10 -> 1012.7152
A11: 7 | B11: 9213214157 | C11: تلفن ، فاكس و اينترنت | D11: ='ريز جاري'!E324 -> 19129 | E11: ='ريز جاري'!G324 -> 0 | F11: =D11/تسعير!E34+E11 -> 5067.2846
A12: 8 | C12: هزينه: کمک هزینه تحصیلی فرزندان | D12: ='ريز جاري'!E366 -> 0 | E12: ='ريز جاري'!G366 -> 0 | F12: =D12/تسعير!E34+E12 -> 0
A13: 9 | B13: 921321415 | C13: كمك هزينه درمان و بيمه كاركنان | D13: ='ريز جاري'!E408 -> 278 | E13: ='ريز جاري'!G408 -> 0 | F13: =D13/تسعير!E34+E13 -> 73.642381
A14: 10 | C14: هزينه هاي خارج از مصوب و تخصيص | D14: ='ريز جاري'!E450 -> 0 | E14: ='ريز جاري'!G450 -> 0 | F14: =D14/تسعير!E34+E14 -> 0
A15: 11 | B15: 9213214152 | C15: هزينه هاي پيش بيني نشده | D15: ='ريز جاري'!E492 -> 1361 | E15: ='ريز جاري'!G492 -> 0 | F15: =D15/تسعير!E34+E15 -> 360.52979
A16: 12 | B16: 9213214159 | C16: هزينه:خريد اقلام مصرفي و پذیرائی | D16: ='ريز جاري'!E114 -> 7133.3 | E16: ='ريز جاري'!G114 -> 0 | F16: =D16/تسعير!E34+E16 -> 1889.6158
A17: 13 | B17: 921321411 | C17: هزينه حقوق كاركنان اعزامي از مركز | E17: 54363 | F17: =D17/تسعير!E34+E17 -> 54363
A18: 14 | F18: =D18/تسعير!E34+E18 -> 0
A19: 15 | F19: =D19/تسعير!E34+E19 -> 0
A20: 16 | F20: =D20/تسعير!E34+E20 -> 0
A21: 17 | F21: =D21/تسعير!E34+E21 -> 0
A22: 18 | F22: =D22/تسعير!E34+E22 -> 0
A23: 19 | F23: =D23/تسعير!E34+E23 -> 0
A24: 20 | F24: =D24/تسعير!E34+E24 -> 0
A25: 21 | F25: =D25/تسعير!E34+E25 -> 0
A26: 22 | F26: =D26/تسعير!E34+E26 -> 0
A27: 23 | F27: =D27/تسعير!E34+E27 -> 0
A28: 24 | F28: =D28/تسعير!E34+E28 -> 0
A29: 25 | F29: =D29/تسعير!E34+E29 -> 0
A30: 26 | F30: =D30/تسعير!E34+E30 -> 0
A31: 27 | F31: =D31/تسعير!E34+E31 -> 0
A32: 28 | F32: =D32/تسعير!E34+E32 -> 0
A33: 29 | F33: =D33/تسعير!E34+E33 -> 0
A34: 30 | F34: =D34/تسعير!E34+E34 -> 0
A35: جمع هزينه هاي جاري | D35: =SUM(D5:D34) -> 38752.8 | E35: =SUM(E5:E34) -> 73954 | F35: =SUM(F5:F34) -> 84219.642
A37: تنظيم كننده: | C37: حسابرس اعزامي: سعید حقانی | E37: رايزني فرهنگي ج.ا.ا:ترکمنستان
A47: ليست كلي هزينه هاي فرهنگي رايزني فرهنگي ج.ا.ايران در ترکمنستان -عشق آباد
A48: سال 1392/1/1 لغایت 92/11/30
D49: نرخ تسعیر: | E49: =تسعير!E34 -> 3.7750002
A50: رديف | B50: كد برنامه | C50: عنوان برنامه | D50: ارز محل | E50: يورو | F50: جمع به يورو
...

Sheet تراز يوروئي و ارزمحل
A2: نمايندگي فرهنگي سفارت ج.ا.ايران در ترکمنستان
A3: تراز عمليات مالي حساب هاي يوروئي از تاريخ 92/1/1 لغايت 92/11/30 ارقام به: يورو
A4: شرح حساب | B4: گردش عمليات مالي | D4: مانده نهايي حساب
B6: بدهكار | C6: بستانكار | D6: بدهكار | E6: بستانكار
A7: بانك:
A8: حساب(جاري1) يورويي به شماره
A9: حساب(جاري2) يورويي به شماره
A10: تنخواه گردان پرداختي:
A11: موجودي صندوق | D11: 84386.8
A12: علي الحساب ها:
A13: يك:علي الحساب جک امانی آقای ناصری | E13: 16058
A14: دو: تعهدات پرداخت نشده(چک آقای ناصری | D14: 16058
A15: سه: پيش پرداخت
A16: وام كاركنان محلي(بدهكار)
A17: حساب سفارت(مانده حساب رايزني نزد سفارت)
A18: حساب تسعير يورو به ارز محل | D18: =تسعير!D34 -> 55452.66
A19: هزينه ها:
A20: هزينه هاي جاري | D20: ='روكش جاري و فرهنگي'!E35-'روكش جاري و فرهنگي'!F17 -> 19591
A21: هزينه هاي فرهنگي | D21: ='روكش جاري و فرهنگي'!E81 -> 1050
A22: هزينه حقوق كاركنان اعزامي از مركز | D22: ='روكش جاري و فرهنگي'!F17 -> 54363
A23: هزينه(1)
A24: هزينه(2)
A25: حساب دريافتي از سازمان بابت بودجه برنامه اي:
A26: بابت بودجه برنامه اي سال جاري | E26: 138000
A27: بابت(1)علي الحساب دريافتي از مركز...
A28: حساب وجوه مصرف نشده سنوات قبل
A29: مانده موجودي نقل از دوره قبل(صندوق+بانك) | E29: 76843.5
A30: دريافتي بابت درآمد
A31: جمع كل: | B31: =SUM(B7:B30) -> 0 | C31: =SUM(C7:C30) -> 0 | D31: =SUM(D7:D30) -> 230901.46 | E31: =SUM(E7:E30) -> 230901.5
A33: بدين وسيله صحت ارقام در ترازنامه نمايندگي به شرح فوق از تاريخ 92/1/1 لغايت 92/12/29 مورد تأئيد است.
A35: حسابرس اعزامي: سعید حقانی | C35: رايزني فرهنگي ج.ا.ايران در ترکمنستان
A43: نمايندگي فرهنگي سفارت ج.ا.ايران در
A44: تراز عمليات مالي حساب هاي ارز محل از تاريخ 92/1/1 لغايت 92/11/30 ارقام به :ارز محل
D45: نرخ ميانگين تسعير: | E45: =تسعير!E34 -> 3.7750002
A46: شرح حساب | B46: گردش عمليات مالي | D46: مانده نهايي حساب
B48: بدهكار | C48: بستانكار | D48: بدهكار | E48: بستانكار
A49: بانك:
A50: حساب(جاري1) ارز محل به شماره
A51: حساب(جاري2) ارز محل به شماره
A52: تنخواه گردان پرداختي:
...

Sheet تراز تلفيقي
A1: نمايندگي فرهنگي سفارت ج.ا.ايران در
A2: تراز عمليات تلفيقي (حساب ارز محل و يورو)
A3: از تاريخ92/1/1 لغايت92/11/30 نرخ ميانگين تسعير: | D3: =تسعير!E34 -> 3.7750002
A4: شرح حساب | B4: حساب هاي يوروئي | D4: معادل يورو حساب هاي ارز محل | F4: مانده نهايي به يورو
B5: بدهكار | C5: بستانكار | D5: بدهكار | E5: بستانكار | F5: بدهكار | G5: بستانكار
A6: بانك:
A7: حساب يوروئي(1) به شماره | B7: ='تراز يوروئي و ارزمحل'!D8 -> 0 | F7: =B7 -> 0
A8: حساب يوروئي(2) به شماره | B8: ='تراز يوروئي و ارزمحل'!D9 -> 0 | F8: =B8 -> 0
A9: حساب ارز محل(1) به شماره | D9: ='تراز يوروئي و ارزمحل'!D50/تسعير!E34 -> 0 | F9: =D9 -> 0
A10: حساب ارز محل(2) به شماره | D10: ='تراز يوروئي و ارزمحل'!D51/تسعير!E34 -> 0 | F10: =D10 -> 0
A11: تنخواه گردان پرداخت:
A12: موجودي صندوق | B12: ='تراز يوروئي و ارزمحل'!D11 -> 84386.8 | C12: ='تراز يوروئي و ارزمحل'!E11 -> 0 | D12: ='تراز يوروئي و ارزمحل'!D53/تسعير!E34 -> 0 | E12: ='تراز يوروئي و ارزمحل'!E53/'تراز يوروئي و ارزمحل'!E45 -> 0 | F12: =D12+B12-E12-C12 -> 84386.8
A13: علي الحساب ها:
A14: يك:علي الحساب جک امانی آقای ناصری | C14: ='تراز يوروئي و ارزمحل'!E13 -> 16058 | E14: ='تراز يوروئي و ارزمحل'!E55/تسعير!E34 -> 0 | G14: =E14+C14 -> 16058
A15: دو: تعهدات پرداخت نشده(چک آقای ناصری | B15: ='تراز يوروئي و ارزمحل'!D14 -> 16058 | D15: ='تراز يوروئي و ارزمحل'!D56/تسعير!E34 -> 0 | F15: =D15+B15 -> 16058
A16: علي الحساب سه | B16: ='تراز يوروئي و ارزمحل'!D15 -> 0 | D16: ='تراز يوروئي و ارزمحل'!D57/تسعير!E34 -> 0 | F16: =D16+B16 -> 0
A17: وام كاركنان محلي | B17: ='تراز يوروئي و ارزمحل'!D16 -> 0 | D17: ='تراز يوروئي و ارزمحل'!D58/تسعير!E34 -> 0 | F17: =D17+B17 -> 0
A18: حساب سفارت | B18: ='تراز يوروئي و ارزمحل'!D17 -> 0 | D18: ='تراز يوروئي و ارزمحل'!D59/تسعير!E34 -> 0 | F18: =D18+B18 -> 0
A19: حساب تسعير يورو به ارز محل | B19: ='تراز يوروئي و ارزمحل'!D18 -> 55452.66 | F19: =B19 -> 55452.66
A20: حساب دريافتي ناشي از تسعير يورو به ارز محل | E20: ='تراز يوروئي و ارزمحل'!E67/تسعير!E34 -> 55452.66 | G20: =E20 -> 55452.66
A21: هزينه ها:
A22: هزينه هاي جاري | B22: ='تراز يوروئي و ارزمحل'!D20 -> 19591 | D22: ='تراز يوروئي و ارزمحل'!D61/تسعير!E34 -> 10265.642 | F22: =D22+B22 -> 29856.642
A23: هزينه هاي فرهنگي | B23: ='تراز يوروئي و ارزمحل'!D21 -> 1050 | D23: ='تراز يوروئي و ارزمحل'!D62/تسعير!E34 -> 45187.018 | F23: =D23+B23 -> 46237.018
A24: هزينه حقوق كاركنان اعزامي از مركز | B24: ='تراز يوروئي و ارزمحل'!D22 -> 54363 | F24: =B24 -> 54363
A25: هزينه يك | B25: ='تراز يوروئي و ارزمحل'!D23 -> 0 | D25: ='تراز يوروئي و ارزمحل'!D63/تسعير!E34 -> 0 | F25: =D25+B25 -> 0
A26: هزينه دو | B26: ='تراز يوروئي و ارزمحل'!D24 -> 0 | D26: ='تراز يوروئي و ارزمحل'!D64/تسعير!E34 -> 0 | F26: =D26+B26 -> 0
A27: هزينه خريد خودرو | F27: =D27+B27 -> 0
A28: هزينه هاي واخواهي شده | F28: =D28+B28 -> 0
A29: حساب دريافتي از سازمان بابت بودجه برنامه اي
A30: بابت بودجه برنامه اي سال جاري | C30: ='تراز يوروئي و ارزمحل'!E26 -> 138000 | G30: =C30 -> 138000
A31: بابت(1) بودجه ساير ادارات | C31: ='تراز يوروئي و ارزمحل'!E27 -> 0 | G31: =C31 -> 0
A32: حساب وجوه مصرف نشده سنوات قبل
A33: مانده موجودي نقل از دوره قبل(صندوق+بانك) | C33: ='تراز يوروئي و ارزمحل'!E29 -> 76843.5 | E33: ='تراز يوروئي و ارزمحل'!E66/تسعير!E34 -> 0 | G33: =E33+C33 -> 76843.5
A34: دريافتي بابت درآمد | C34: ='تراز يوروئي و ارزمحل'!E30 -> 0 | E34: ='تراز يوروئي و ارزمحل'!E68/تسعير!E34 -> 0 | G34: =E34+C34 -> 0
A35: جمع كل | B35: =SUM(B6:B34) -> 230901.46 | C35: =SUM(C6:C34) -> 230901.5 | D35: =SUM(D6:D34) -> 55452.66 | E35: =SUM(E6:E34) -> 55452.66 | F35: =SUM(F6:F34) -> 286354.12 | G35: =SUM(G6:G34) -> 286354.16
A36: بدين وسيله صحت ارقام در ترازنامه نمايندگي به شرح فوق از تاريخ 92/1/1 لغايت 92/11/30 با نرخ ميانگين تسعير: 3.775
A37: برابر با يك يورو مورد تأئيد است.
A38: حسابرس اعزامي:سعید حقانی | D38: رايزني فرهنگي ج.ا.ايران در ترکمنستان

Sheet ریزحقوق کارکنان محلی
A1: حقوق،بازخريدي و...كاركنان بومي کد برنامه: فروردین سال
A2: حقوق،بازخريدي و...كاركنان بومي کد برنامه: اردیبهست سال
A3: حقوق،بازخريدي و...كاركنان بومي کد برنامه: خرداد سال
A4: حقوق،بازخريدي و...كاركنان بومي کد برنامه: تیر سال
A5: حقوق،بازخريدي و...كاركنان بومي کد برنامه: مرداد سال
A6: حقوق،بازخريدي و...كاركنان بومي کد برنامه: شهریور سال
A7: حقوق،بازخريدي و...كاركنان بومي کد برنامه: مهر سال
A8: حقوق،بازخريدي و...كاركنان بومي کد برنامه: آبان سال
A9: حقوق،بازخريدي و...كاركنان بومي کد برنامه: آذر سال
A10: حقوق،بازخريدي و...كاركنان بومي کد برنامه: دی سال
A11: حقوق،بازخريدي و...كاركنان بومي کد برنامه: بهمن سال
A12: حقوق،بازخريدي و...كاركنان بومي کد برنامه: اسفند سال
A32: نمایندگی فرهنگی ج.ا.ایران در
A33: حقوق،بازخريدي و...كاركنان بومي کد برنامه: فروردین سال | G33: نرخ تسعیر: | H33: =تسعير!E34 -> 3.7750002
A34: ردیف | B34: نام و نام خانوادگی | C34: شغل | D34: حقوق ماهانه به یورو | E34: حقوق ماهانه به ارز محل | F34: ساعت اضافه کار | G34: مبلغ اضافه کار به یورو | H34: جمع کل پرداختی به یورو | I34: توضیحات
A35: 1 | H35: =D35+(E35/H33)+G35 -> 0
A36: 2 | H36: =D36+E36/H33+G36 -> 0
A37: 3 | H37: =D37+E37/H33+G37 -> 0
A38: 4 | H38: =D38+E38/H33+G38 -> 0
A39: 5 | H39: =D39+E39/H33+G39 -> 0
A40: 6 | H40: =D40+E40/H33+G40 -> 0
A41: 7 | H41: =D41+E41/H33+G41 -> 0
A42: 8 | H42: =D42+E42/H33+G42 -> 0
A43: 9 | H43: =D43+E43/H33+G43 -> 0
A44: 10 | H44: =D44+E44/H33+G44 -> 0
A45: 11 | H45: =D45+E45/H33+G45 -> 0
A46: 12 | H46: =D46+E46/H33+G46 -> 0
A47: جمع کل: | D47: =SUM(D35:D46) -> 0 | E47: =SUM(E35:E46) -> 0 | F47: =SUM(F35:F46) -> 0 | G47: =SUM(G35:G46) -> 0 | H47: =SUM(H35:H46) -> 0
A48: بدینوسیله گواهی میشود مبلغ یورو بابت حقوق فروردین ماه و مبلغ یورو بابت اضافه کاری جمعآ به مبلغ یورو به تعداد نفر از کارکنان محلی رایزنی فرهنگی ج. ا.ایران در کشور از محل بودجه برنامه مصوب پرداخت گردیده است. صحن مندرجات مورد تأئید می باشد.
A51: کارشناس فرهنگی | G51: مهر و امضاء رایزنی فرهنگی
A58: نمایندگی فرهنگی ج.ا.ایران در
A59: حقوق،بازخريدي و...كاركنان بومي کد برنامه: اردیبهشت سال | G59: نرخ تسعیر: | H59: =تسعير!E34 -> 3.7750002
A60: ردیف | B60: نام و نام خانوادگی | C60: شغل | D60: حقوق ماهانه به یورو | E60: حقوق ماهانه به ارز محل | F60: ساعت اضافه کار | G60: مبلغ اضافه کار به یورو | H60: جمع کل پرداختی به یورو | I60: توضیحات
A61: 1 | H61: =D61+E61/H59+G61 -> 0
A62: 2 | H62: =D62+E62/H59+G62 -> 0
A63: 3 | H63: =D63+E63/H59+G63 -> 0
A64: 4 | H64: =D64+E64/H59+G64 -> 0
A65: 5 | H65: =D65+E65/H59+G65 -> 0
A66: 6 | H66: =D66+E66/H59+G66 -> 0
A67: 7 | H67: =D67+E67/H59+G67 -> 0
...

Sheet روکش حقوق محلی
A1: نمایندگی فرهنگی سفارت ج.ا.ایران در
A2: روکش لیست هزینه های حقوق بازخریدی و پاداش کارکنان محلی
A3: کد برنامه مصوب: | D3: نرخ تسعیر: | E3: =تسعير!E34 -> 3.7750002
A4: ردیف | B4: شرح هزینه | C4: ارز محل | D4: اضافه کاری یورو | E4: حقوق یورو | F4: جمع کل به یورو
A5: 1 | B5: حقوق و اضافه کاری فروردین ماه سال | C5: ='ریزحقوق کارکنان محلی'!E47 -> 0 | D5: ='ریزحقوق کارکنان محلی'!G47 -> 0 | E5: ='ریزحقوق کارکنان محلی'!D47 -> 0 | F5: ='ریزحقوق کارکنان محلی'!H47 -> 0
A6: 2 | B6: حقوق و اضافه کاری اردیبهشت ماه سال | C6: ='ریزحقوق کارکنان محلی'!E73 -> 0 | D6: ='ریزحقوق کارکنان محلی'!G73 -> 0 | E6: ='ریزحقوق کارکنان محلی'!D73 -> 0 | F6: ='ریزحقوق کارکنان محلی'!H73 -> 0
A7: 3 | B7: حقوق و اضافه کاری خرداد ماه سال | C7: ='ریزحقوق کارکنان محلی'!E99 -> 0 | D7: ='ریزحقوق کارکنان محلی'!G99 -> 0 | E7: ='ریزحقوق کارکنان محلی'!D99 -> 0 | F7: ='ریزحقوق کارکنان محلی'!H99 -> 0
A8: 4 | B8: حقوق و اضافه کاری تیر ماه سال | C8: ='ریزحقوق کارکنان محلی'!E125 -> 0 | D8: ='ریزحقوق کارکنان محلی'!G125 -> 0 | E8: ='ریزحقوق کارکنان محلی'!D125 -> 0 | F8: ='ریزحقوق کارکنان محلی'!H125 -> 0
A9: 5 | B9: حقوق و اضافه کاری مرداد ماه سال | C9: ='ریزحقوق کارکنان محلی'!E151 -> 0 | D9: ='ریزحقوق کارکنان محلی'!G151 -> 0 | E9: ='ریزحقوق کارکنان محلی'!D151 -> 0 | F9: ='ریزحقوق کارکنان محلی'!H151 -> 0
A10: 6 | B10: حقوق و اضافه کاری شهریور ماه سال | C10: ='ریزحقوق کارکنان محلی'!E177 -> 0 | D10: ='ریزحقوق کارکنان محلی'!G177 -> 0 | E10: ='ریزحقوق کارکنان محلی'!D177 -> 0 | F10: ='ریزحقوق کارکنان محلی'!H177 -> 0
A11: 7 | B11: حقوق و اضافه کاری مهر ماه سال | C11: ='ریزحقوق کارکنان محلی'!E203 -> 0 | D11: ='ریزحقوق کارکنان محلی'!G203 -> 0 | E11: ='ریزحقوق کارکنان محلی'!D203 -> 0 | F11: ='ریزحقوق کارکنان محلی'!H203 -> 0
A12: 8 | B12: حقوق و اضافه کاری آبان ماه سال | C12: ='ریزحقوق کارکنان محلی'!E229 -> 0 | D12: ='ریزحقوق کارکنان محلی'!G229 -> 0 | E12: ='ریزحقوق کارکنان محلی'!D229 -> 0 | F12: ='ریزحقوق کارکنان محلی'!H229 -> 0
A13: 9 | B13: حقوق و اضافه کاری آذر ماه سال | C13: ='ریزحقوق کارکنان محلی'!E255 -> 0 | D13: ='ریزحقوق کارکنان محلی'!G255 -> 0 | E13: ='ریزحقوق کارکنان محلی'!D255 -> 0 | F13: ='ریزحقوق کارکنان محلی'!H255 -> 0
A14: 10 | B14: حقوق و اضافه کاری دی ماه سال | C14: ='ریزحقوق کارکنان محلی'!E281 -> 0 | D14: ='ریزحقوق کارکنان محلی'!G281 -> 0 | E14: ='ریزحقوق کارکنان محلی'!D281 -> 0 | F14: ='ریزحقوق کارکنان محلی'!H281 -> 0
A15: 11 | B15: حقوق و اضافه کاری بهمن ماه سال | C15: ='ریزحقوق کارکنان محلی'!E307 -> 0 | D15: ='ریزحقوق کارکنان محلی'!G307 -> 0 | E15: ='ریزحقوق کارکنان محلی'!D307 -> 0 | F15: ='ریزحقوق کارکنان محلی'!H307 -> 0
A16: 12 | B16: حقوق و اضافه کاری اسفند ماه سال | C16: ='ریزحقوق کارکنان محلی'!E333 -> 0 | D16: ='ریزحقوق کارکنان محلی'!G333 -> 0 | E16: ='ریزحقوق کارکنان محلی'!D333 -> 0 | F16: ='ریزحقوق کارکنان محلی'!H333 -> 0
A17: 13 | B17: هزینه یک:
A18: 14 | B18: هزینه دو:
A19: 15 | B19: هزینه سه:
A20: 16 | B20: هزینه چهار:
A21: 17 | B21: هزینه پنج:
A22: 18
A23: 19
A24: 20
A25: جمع کل: | C25: =SUM(C5:C24) -> 0 | D25: =SUM(D5:D24) -> 0 | E25: =SUM(E5:E24) -> 0 | F25: =SUM(F5:F24) -> 0
A26: جمع یوروئی | D26: =E25+D25 -> 0 | F26: =F25 -> 0
A27: بدینوسیله گواهی میشود مبلغ ارز محل ( ) با نرخ تسعیر برابر یورو و احتساب مبلغ هزینه یورویی جمعأ به مبلغ یورو از تاریخ لغایت از محل بودجه برنامه مصوب هزینه گردیه است.
A29: حسابرس اعزامی | D29: رایزنی فرهنگی

Sheet فهرست وجوه ارسالي
A1: فهرست وجوه ارسالي از سازمان فرهنگ و ارتباطات اسلامي
A2: نمايندگي فرهنگي سفارت ج.ا.ايران در ترکمنستان
A3: از تاريخ 91/7/28 لغايت 91/12/29
G4: ارقام: به يورو
A5: رديف | B5: شرح برنامه | C5: شماره سند | D5: شماره حواله | E5: تاريخ حواله | F5: بودجه ارسالي | G5: بودجه واريز شده به حساب | H5: كارمزد بانكي
A6: 1 | B6: جاری و فرهنگی | F6: 66875 | G6: 66875
A7: 2 | B7: حقوق آقای اسماعیل زاده | F7: 30429 | G7: 30429
A8: 3 | B8: حقوق آقای نعمتی زاده | F8: 23504 | G8: 23504 | H8: =F8-G8 -> 0
A9: 4 | B9: حقوق آقای میرمحمدی | F9: 9192 | G9: 9192 | H9: =F9-G9 -> 0
A10: 5 | B10: اعزام مبلغ | F10: 4000 | G10: 4000 | H10: =F10-G10 -> 0
A11: 6 | B11: دهه ی فجر | F11: 4000 | G11: 4000 | H11: =F11-G11 -> 0
A12: 7 | H12: =F12-G12 -> 0
A13: 8 | H13: =F13-G13 -> 0
A14: 9 | H14: =F14-G14 -> 0
A15: 10 | H15: =F15-G15 -> 0
A16: 11 | H16: =F16-G16 -> 0
A17: 12 | H17: =F17-G17 -> 0
A18: 13 | H18: =F18-G18 -> 0
A19: 14 | H19: =F19-G19 -> 0
A20: جمع كل | F20: =SUM(F6:F19) -> 138000 | G20: =SUM(G6:G19) -> 138000 | H20: =SUM(H6:H19) -> 0
A21: بدينوسيله گواهي مي شود مبالغ فوق الذكر بابت بودجه جاري و فرهنگي تحویلی به نمايندگي فرهنگی ج .ا.ایران در ترکمنستان
A22: مراتب مورد تاييد است.
A24: حسابرس اعزامي از مركز: سعید حقانی | F24: رايزن فرهنگي ج.ا. ايران در ترکمستان
G25: آقای اسماعیل زاده

Sheet هزينه و انحراف 2
A1: صورت خلاصه هزینه های جاری نمایندگی فرهنگی جمهوری اسلامی ایران در تركمنستان از تاریخ 1392/1/1لغایت 1392/11/30
A4: ردیف | B4: کد برنامه | C4: عنوان هزینه | D4: بودجه | E4: هزینه | F4: معادل | G4: هزینه | H4: جمع عملکرد | I4: بودجه | J4: انحراف | K4: تعداد سند به برگ
D5: مصوب | E5: به ارز محل | F5: یوروئی هزینه | G5: به یورو | H5: هزینه | I5: تخصیص | J5: هزینه
A6: 1 | B6: 921321412 921321413 | C6: حقوق کارکنان محلی و بازخریدی رایزنی | F6: =E6/E28 -> 0 | G6: 19591 | H6: =F6+G6 -> 19591 | I6: 21073 | J6: =I6-H6 -> 1482
A7: 2 | B7: 921321415 | C7: کمک هزینه درمان وبیمه کارکنان | E7: 278 | F7: =E7/E28 -> 73.642381 | H7: =F7+G7 -> 73.642381 | I7: 1000 | J7: =I7-H7 -> 926.35762
A8: 3 | B8: 921321414 | C8: کمک هزینه تحصیلی فرزندان کارکنان اعزامی مرکز | E8: 2109 | F8: =E8/E28 -> 558.67547 | H8: =F8+G8 -> 558.67547 | I8: 1000 | J8: =I8-H8 -> 441.32453
A9: 4 | B9: 9213214155 | C9: هزینه های تعمير و نگهداري خودرو | E9: 3535.5 | F9: =E9/E28 -> 936.55625 | H9: =F9+G9 -> 936.55625 | I9: 2000 | J9: =I9-H9 -> 1063.4437
A10: 5 | B10: 9213214156 | C10: هزينه آب؛برق؛گاز؛وسایر سوختها | E10: 2109 | F10: =E10/E28 -> 558.67547 | H10: =F10+G10 -> 558.67547 | I10: 1000 | J10: =I10-H10 -> 441.32453
A11: 6 | B11: 9213214157 | C11: هزینه تلفن ؛ فکس ؛ واينترنت | E11: 19129 | F11: =E11/E28 -> 5067.2846 | H11: =F11+G11 -> 5067.2846 | I11: 6000 | J11: =I11-H11 -> 932.71544
A12: 7 | B12: 9213214159 | C12: خرید اقلام مصرفی و پذیرائی | E12: 7133 | F12: =E12/E28 -> 1889.5363 | H12: =F12+G12 -> 1889.5363 | I12: 2000 | J12: =I12-H12 -> 110.46365
A13: 8 | F13: =E13/E28 -> 0 | H13: =G13+F13 -> 0 | J13: =I13-H13 -> 0
A14: 9 | F14: =E14/E28 -> 0 | H14: =G14+F14 -> 0 | J14: =I14-H14 -> 0
A15: 10 | F15: =E15/E28 -> 0 | H15: =G15+F15 -> 0 | J15: =I15-H15 -> 0
A16: 11 | F16: =E16/E28 -> 0 | H16: =G16+F16 -> 0 | J16: =I16-H16 -> 0
A17: 12 | F17: =E17/E28 -> 0 | H17: =G17+F17 -> 0 | J17: =I17-H17 -> 0
A18: 13 | F18: =E18/E28 -> 0 | H18: =G18+F18 -> 0 | J18: =I18-H18 -> 0
A19: 14 | B19: 9213214160 | C19: حمل نقل و ارتباطات | E19: 3823 | F19: =E19/E28 -> 1012.7152 | H19: 0 | I19: 2000 | J19: =I19-H19 -> 2000
A20: 15 | C20: هزینه های بانکی و پست | F20: =E20/E28 -> 0 | H20: =F20+G20 -> 0 | J20: =I20-H20 -> 0
A21: 16 | B21: 9213214152 | C21: هزینه های پیش بینی نشده در امور فرهنگی و جاری | E21: 1361 | F21: =E21/E28 -> 360.52979 | H21: =F21+G21 -> 360.52979 | I21: 2400 | J21: =I21-H21 -> 2039.4702
A22: 17 | B22: 9213214154 | C22: هزينه های تعمير و نگهداري اماكن و وسايل اداري | E22: 1384 | F22: =E22/E28 -> 366.6225 | H22: =F22+G22 -> 366.6225 | I22: 1000 | J22: =I22-H22 -> 633.3775
A23: 18 | C23: حقوق اعزامی از مرکز | F23: =E23/E28 -> 0 | H23: =F23+G23 -> 0 | J23: =I23-H23 -> 0
A24: 19 | C24: علی الحساب حقوق کارکنان محلی | F24: =E24/E28 -> 0 | H24: =F24+G24 -> 0 | J24: =I24-H24 -> 0
A25: 20 | C25: هزینه اجاره ساختمان مرکز آموزش | F25: =E25/E28 -> 0 | H25: =F25+G25 -> 0 | J25: =I25-H25 -> 0
A26: 21 | C26: علی الحساب حقوق کارکنان اعزامی | F26: =E26/E28 -> 0 | H26: =F26+G26 -> 0 | J26: =I26-H26 -> 0
A27: جمع کل هزینه های جاری و حقوق | D27: =SUM(D6:D25) -> 0 | E27: =SUM(E6:E25) -> 40861.5 | F27: =SUM(F6:F25) -> 10824.238 | G27: =SUM(G6:G25) -> 19591 | H27: =SUM(H6:H26) -> 29402.523 | I27: =SUM(I6:I25) -> 39473 | J27: =SUM(J6:J25) -> 10070.477 | K27: =SUM(K6:K26) -> 0
D28: تسعير: | E28: =تسعير!E34 -> 3.7750002 | G28: آقای اسماعیل زاده
C29: حسابرس اعزامي: سعید حقانی | G29: رایزن فرهنگی جمهوری اسلامی ایران در تركمنستان
A37: صورت خلاصه هزینه های فرهنگی نمایندگی فرهنگی جمهوری اسلامی ایران در تركمنستان از تاریخ 1392/1/1لغایت 1392/11/30
A40: ردیف | B40: کد برنامه | C40: عنوان هزینه | D40: بودجه | E40: هزینه | F40: معادل | G40: هزینه | H40: جمع عملکرد | I40: بودجه | J40: انحراف | K40: تعداد سند به برگ
D41: مصوب | E41: به ارز محل | F41: یوروئی هزینه | G41: به یورو | H41: هزینه | I41: تخصیص | J41: هزینه
A42: 1 | B42: 9213214114 | C42: برگزاری جشن نوروز | E42: 8854.2 | F42: =E42/E78 -> 2345.4833 | G42: 650 | H42: =F42+G42 -> 2995.4833 | I42: 2500 | J42: =I42-H42 -> -495.48335
A43: 2 | B43: 9213214115 | C43: برگزاری مراسم مردمی سالگرد ارتحال امام ره | E43: 4535 | F43: =E43/E78 -> 1201.3245 | H43: =F43+G43 -> 1201.3245 | I43: 2500 | J43: =I43-H43 -> 1298.6755
A44: 3 | B44: 9213214116 | C44: برگزاری مراسم ویژه برزگداشت نیمه شعبان | E44: 6783 | F44: =E44/E78 -> 1796.8211 | H44: =F44+G44 -> 1796.8211 | I44: 2000 | J44: =I44-H44 -> 203.17888
A45: 4 | B45: 9213214117 | C45: انتشار 4 شماره از نشریه دوره ای خاوران | E45: 6140 | F45: =E45/E78 -> 1626.49 | H45: =F45+G45 -> 1626.49 | I45: 3000 | J45: =I45-H45 -> 1373.51 | K45: 4
A46: 5 | B46: 9213214130 | C46: برگزاری مناسبتهای دینی و مذهبی(رمضان محرم ولادتها و وفاتهاو... | E46: 34945 | F46: =E46/E78 -> 9256.9533 | H46: =F46+G46 -> 9256.9533 | I46: 6000 | J46: =I46-H46 -> -3256.9533
A47: 6 | C47: برگزاری هفته فرهنگی | F47: =E47/E78 -> 0 | H47: =F47+G47 -> 0 | J47: =I47-H47 -> 0
A48: 7 | C48: برگزاری روزهای دوستی کودکان و نوجوانان ایران و ترکمنستان | F48: =E48/E78 -> 0 | H48: =F48+G48 -> 0 | J48: =I48-H48 -> 0
A49: 8 | C49: برگزاری نمایشگاه قرآنی در ماه مبارک رمضان | F49: =E49/E78 -> 0 | H49: =G49+F49 -> 0 | J49: =I49-H49 -> 0
A50: 9 | B50: 9213214120 | C50: برگزاري همايش امام رضا (ع) در مرو | E50: 15054 | F50: =E50/E78 -> 3987.8144 | H50: =G50+F50 -> 3987.8144 | I50: 4000 | J50: =I50-H50 -> 12.185592
A51: 10 | C51: برگزاري مراسم مردمي روز قدس | F51: =E51/E78 -> 0 | H51: =G51+F51 -> 0 | J51: =I51-H51 -> 0
...
