Workbook

Sheet تسعير
A1: رايزني فرهنگي جمهوري اسلامي ايران در
A2: سال 13
A4: رديف | B4: تاريخ | C4: شماره چك/نقدي | D4: مبلغ يورو | E4: نرخ تسعير | F4: مبلغ تبديلي به: | G4: ملاحضات
A5: 1 | E5: =F5/D5 -> #DIV/0!
A6: 2 | E6: =F6/D6 -> #DIV/0!
A7: 3 | E7: =F7/D7 -> #DIV/0!
A8: 4 | E8: =F8/D8 -> #DIV/0!
A9: 5 | E9: =F9/D9 -> #DIV/0!
A10: 6 | E10: =F10/D10 -> #DIV/0!
A11: 7 | E11: =F11/D11 -> #DIV/0!
A12: 8 | E12: =F12/D12 -> #DIV/0!
A13: 9 | E13: =F13/D13 -> #DIV/0!
A14: 10 | E14: =F14/D14 -> #DIV/0!
A15: 11 | E15: =F15/D15 -> #DIV/0!
A16: 12 | E16: =F16/D16 -> #DIV/0!
... A33: 29 | E33: =F33/D33 -> #DIV/0!
A34: جمع كل | D34: =SUM(D5:D33) -> 0 | E34: =F34/D34 -> #DIV/0! | F34: =SUM(F5:F33) -> 0
A35: مصرف اين دوره حسب فهرست هزينه ها: | F35: ='روكش جاري و فرهنگي'!D81+'روكش جاري و فرهنگي'!D35 -> 0
A36: مانده موجودي قابل انتقال به دوره بعد: | D36: =F36/E36 -> #DIV/0! | E36: =F34/D34 -> #DIV/0! | F36: =F34-F35 -> 0
A38: تنظيم كننده: | D38: حسابرس اعزامي: | F38: رايزني فرهنگي ج .ا.ا:

Sheet ريز جاري
A1: رايزني فرهنگي ج.ا.ايران در: | J1: هزينه بانكي(كارمزد)
A2: سال: | J2: حقوق،بازخريدي و...كاركنان بومي
A3: هزينه جاري:بانكي(كارمزد) | F3: نرخ تسعير: | G3: =تسعير!E34 -> #DIV/0! | J3: خريد اقلام مصرفي
A4: رديف | B4: تارخ سند | C4: شرح | D4: سند | E4: ارز محل | F4: معادل به يورو | G4: يورو | H4: جمع به يورو | J4: هزينه آب برق گاز و ساير سوخت ها
A5: 1 | B5: 30/12/91 | F5: =E5/G3 -> #DIV/0! | H5: =G5+F5 -> #DIV/0! | J5: تعمير و نگهداري خودرو
A6: 2 | F6: =E6/G3 -> #DIV/0! | H6: =G6+F6 -> #DIV/0! | J6: ترميم و نگهداري جزئي ساختمان
A7: 3 | F7: =E7/G3 -> #DIV/0! | H7: =G7+F7 -> #DIV/0! | J7: حمل و نقل و ارتباطات
A8: 4 | F8: =E8/G3 -> #DIV/0! | H8: =G8+F8 -> #DIV/0! | J8: تلفن،فاكس و اينترنت
A9: 5 | F9: =E9/G3 -> #DIV/0! | H9: =G9+F9 -> #DIV/0! | J9: هزينه اجاره ساختمان نمايندگي
A10: 6 | F10: =E10/G3 -> #DIV/0! | H10: =G10+F10 -> #DIV/0! | J10: كمك هزينه درمان و بيمه كاركنان
A11: 7 | F11: =E11/G3 -> #DIV/0! | H11: =G11+F11 -> #DIV/0! | J11: هزينه هاي خارج از مصوب و تخصيص
A12: 8 | F12: =E12/G3 -> #DIV/0! | H12: =G12+F12 -> #DIV/0! | J12: هزينه هاي پيش بيني نشده
A13: 9 | F13: =E13/G3 -> #DIV/0! | H13: =G13+F13 -> #DIV/0!
A14: 10 | F14: =E14/G3 -> #DIV/0! | H14: =G14+F14 -> #DIV/0!
A15: 11 | F15: =E15/G3 -> #DIV/0! | H15: =G15+F15 -> #DIV/0!
A16: 12 | F16: =E16/G3 -> #DIV/0! | H16: =G16+F16 -> #DIV/0!
A17: 13 | F17: =E17/G3 -> #DIV/0! | H17: =G17+F17 -> #DIV/0!
A18: 14 | F18: =E18/G3 -> #DIV/0! | H18: =G18+F18 -> #DIV/0!
A19: 15 | F19: =E19/G3 -> #DIV/0! | H19: =G19+F19 -> #DIV/0!
A20: 16 | F20: =E20/G3 -> #DIV/0! | H20: =G20+F20 -> #DIV/0!
A21: 17 | F21: =E21/G3 -> #DIV/0! | H21: =G21+F21 -> #DIV/0!
A22: 18 | F22: =E22/G3 -> #DIV/0! | H22: =G22+F22 -> #DIV/0!
A23: 19 | F23: =E23/G3 -> #DIV/0! | H23: =G23+F23 -> #DIV/0!
A24: 20 | F24: =E24/G3 -> #DIV/0! | H24: =G24+F24 -> #DIV/0!
A25: 21 | F25: =E25/G3 -> #DIV/0! | H25: =G25+F25 -> #DIV/0!
A26: 22 | F26: =E26/G3 -> #DIV/0! | H26: =G26+F26 -> #DIV/0!
A27: 23 | F27: =E27/G3 -> #DIV/0! | H27: =G27+F27 -> #DIV/0!
A28: 24 | F28: =E28/G3 -> #DIV/0! | H28: =G28+F28 -> #DIV/0!
A29: 25 | F29: =E29/G3 -> #DIV/0! | H29: =G29+F29 -> #DIV/0!
A30: جمع كل | E30: =SUM(E5:E29) -> 0 | F30: =E30/G3 -> #DIV/0! | G30: =SUM(G5:G29) -> 0 | H30: =SUM(H5:H29) -> #DIV/0!
A32: تنظيم كننده: | C32: حسابرس اعزامي: | E32: رايزن فرهنگي:
A43: رايزني فرهنگي ج.ا.ايران در:
A44: سال:
A45: هزينه جاري:حقوق، بازخريدي و...كاركنان بومي | F45: نرخ تسعير: | G45: =تسعير!E34 -> #DIV/0!
A46: رديف | B46: تارخ سند | C46: شرح | D46: سند | E46: ارز محل | F46: معادل به يورو | G46: يورو | H46: جمع به يورو
A47: 1 | B47: 15/15/91 | C47: حقوق و اضافه کاری فروردین ماه سال | F47: =E47/G3 -> #DIV/0! | H47: =G47+F47 -> #DIV/0!
A48: 2 | C48: حقوق و اضافه کاری اردیبهشت ماه سال | F48: =E48/G3 -> #DIV/0! | H48: =G48+F48 -> #DIV/0!
A49: 3 | C49: حقوق و اضافه کاری خرداد ماه سال | F49: =E49/G3 -> #DIV/0! | H49: =G49+F49 -> #DIV/0!
A50: 4 | C50: حقوق و اضافه کاری تیر ماه سال | F50: =E50/G3 -> #DIV/0! | H50: =G50+F50 -> #DIV/0!
A51: 5 | C51: حقوق و اضافه کاری مرداد ماه سال | F51: =E51/G3 -> #DIV/0! | H51: =G51+F51 -> #DIV/0!
...

Sheet ريز فرهنگي
A1: رايزني فرهنگي ج.ا.ايران در: | J1: هزينه يك:برگزاري جشن نوروز
A2: سال: | J2: هزينه دو:برگزاري مراسم ارتحال امام
A3: هزينه فرهنگي يك: برگزاري جشن نوروز | F3: نرخ تسعير: | G3: =تسعير!E34 -> #DIV/0! | J3: هزينه سه:
A4: رديف | B4: تارخ سند | C4: شرح | D4: سند | E4: ارز محل | F4: معادل به يورو | G4: يورو | H4: جمع به يورو | J4: هزينه چهار:
A5: 1 | B5: 30/12/91 | F5: =E5/G3 -> #DIV/0! | H5: =G5+F5 -> #DIV/0! | J5: هزينه پنج:
A6: 2 | F6: =E6/G3 -> #DIV/0! | H6: =G6+F6 -> #DIV/0! | J6: هزينه شش:
A7: 3 | F7: =E7/G3 -> #DIV/0! | H7: =G7+F7 -> #DIV/0! | J7: هزينه هفت:
A8: 4 | F8: =E8/G3 -> #DIV/0! | H8: =G8+F8 -> #DIV/0! | J8: هزينه هشت:
A9: 5 | F9: =E9/G3 -> #DIV/0! | H9: =G9+F9 -> #DIV/0! | J9: هزينه نه:
A10: 6 | F10: =E10/G3 -> #DIV/0! | H10: =G10+F10 -> #DIV/0! | J10: هزينه ده:
A11: 7 | F11: =E11/G3 -> #DIV/0! | H11: =G11+F11 -> #DIV/0!
A12: 8 | F12: =E12/G3 -> #DIV/0! | H12: =G12+F12 -> #DIV/0!
A13: 9 | F13: =E13/G3 -> #DIV/0! | H13: =G13+F13 -> #DIV/0!
A14: 10 | F14: =E14/G3 -> #DIV/0! | H14: =G14+F14 -> #DIV/0!
A15: 11 | F15: =E15/G3 -> #DIV/0! | H15: =G15+F15 -> #DIV/0!
A16: 12 | F16: =E16/G3 -> #DIV/0! | H16: =G16+F16 -> #DIV/0!
A17: 13 | F17: =E17/G3 -> #DIV/0! | H17: =G17+F17 -> #DIV/0!
A18: 14 | F18: =E18/G3 -> #DIV/0! | H18: =G18+F18 -> #DIV/0!
A19: 15 | F19: =E19/G3 -> #DIV/0! | H19: =G19+F19 -> #DIV/0!
A20: 16 | F20: =E20/G3 -> #DIV/0! | H20: =G20+F20 -> #DIV/0!
A21: 17 | F21: =E21/G3 -> #DIV/0! | H21: =G21+F21 -> #DIV/0!
A22: 18 | F22: =E22/G3 -> #DIV/0! | H22: =G22+F22 -> #DIV/0!
A23: 19 | F23: =E23/G3 -> #DIV/0! | H23: =G23+F23 -> #DIV/0!
A24: 20 | F24: =E24/G3 -> #DIV/0! | H24: =G24+F24 -> #DIV/0!
A25: 21 | F25: =E25/G3 -> #DIV/0! | H25: =G25+F25 -> #DIV/0!
A26: 22 | F26: =E26/G3 -> #DIV/0! | H26: =G26+F26 -> #DIV/0!
A27: 23 | F27: =E27/G3 -> #DIV/0! | H27: =G27+F27 -> #DIV/0!
A28: 24 | F28: =E28/G3 -> #DIV/0! | H28: =G28+F28 -> #DIV/0!
A29: 25 | F29: =E29/G3 -> #DIV/0! | H29: =G29+F29 -> #DIV/0!
A30: جمع كل | E30: =SUM(E5:E29) -> 0 | F30: =E30/G3 -> #DIV/0! | G30: =SUM(G5:G29) -> 0 | H30: =SUM(H5:H29) -> #DIV/0!
A32: تنظيم كننده: | C32: حسابرس اعزامي: | E32: رايزن فرهنگي:
A43: رايزني فرهنگي ج.ا.ايران در:
A44: سال:
A45: هزينه فرهنگي دو: برگزاري مراسم ارتحال امام | F45: نرخ تسعير: | G45: =تسعير!E34 -> #DIV/0!
A46: رديف | B46: تارخ سند | C46: شرح | D46: سند | E46: ارز محل | F46: معادل به يورو | G46: يورو | H46: جمع به يورو
A47: 1 | B47: 30/12/91 | F47: =E47/G3 -> #DIV/0! | H47: =G47+F47 -> #DIV/0!
A48: 2 | F48: =E48/G3 -> #DIV/0! | H48: =G48+F48 -> #DIV/0!
A49: 3 | F49: =E49/G3 -> #DIV/0! | H49: =G49+F49 -> #DIV/0!
A50: 4 | F50: =E50/G3 -> #DIV/0! | H50: =G50+F50 -> #DIV/0!
A51: 5 | F51: =E51/G3 -> #DIV/0! | H51: =G51+F51 -> #DIV/0!
...

Sheet روكش جاري و فرهنگي
A1: ليست كلي هزينه هاي جاري رايزني فرهنگي ج.ا.ايران در
A2: سال 13
A4: رديف | B4: كد برنامه | C4: عنوان برنامه | D4: ارز محل | E4: يورو | F4: جمع به يورو
A5: 1 | C5: هزينه بانكي | D5: ='ريز جاري'!E30 -> 0 | E5: ='ريز جاري'!G30 -> 0 | F5: =D5/تسعير!E34+E5 -> #DIV/0!
A6: 2 | C6: حقوق بازخريدي و ... كاركنان بومي | D6: ='ريز جاري'!E72 -> 0 | E6: ='ريز جاري'!G72 -> 0 | F6: =D6/تسعير!E34+E6 -> #DIV/0!
A7: 3 | C7: هزينه آب برق گاز و ساير سوخت ها | D7: ='ريز جاري'!E156 -> 0 | E7: ='ريز جاري'!G156 -> 0 | F7: =D7/تسعير!E34+E7 -> #DIV/0!
A8: 4 | C8: تعمير و نگهداري خودرو | D8: ='ريز جاري'!E198 -> 0 | E8: ='ريز جاري'!G198 -> 0 | F8: =D8/تسعير!E34+E8 -> #DIV/0!
A9: 5 | C9: ترميم و نگهداري جزئي ساختمان | D9: ='ريز جاري'!E240 -> 0 | E9: ='ريز جاري'!G240 -> 0 | F9: =D9/تسعير!E34+E9 -> #DIV/0!
A10: 6 | C10: حمل و نقل و ارتباطات | D10: ='ريز جاري'!E282 -> 0 | E10: ='ريز جاري'!G282 -> 0 | F10: =D10/تسعير!E34+E10 -> #DIV/0!
A11: 7 | C11: تلفن ، فاكس و اينترنت | D11: ='ريز جاري'!E324 -> 0 | E11: ='ريز جاري'!G324 -> 0 | F11: =D11/تسعير!E34+E11 -> #DIV/0!
A12: 8 | C12: هزينه اجاره ساختمان نمايندگي | D12: ='ريز جاري'!E366 -> 0 | E12: ='ريز جاري'!G366 -> 0 | F12: =D12/تسعير!E34+E12 -> #DIV/0!
A13: 9 | C13: كمك هزينه درمان و بيمه كاركنان | D13: ='ريز جاري'!E408 -> 0 | E13: ='ريز جاري'!G408 -> 0 | F13: =D13/تسعير!E34+E13 -> #DIV/0!
A14: 10 | C14: هزينه هاي خارج از مصوب و تخصيص | D14: ='ريز جاري'!E450 -> 0 | E14: ='ريز جاري'!G450 -> 0 | F14: =D14/تسعير!E34+E14 -> #DIV/0!
A15: 11 | C15: هزينه هاي پيش بيني نشده | D15: ='ريز جاري'!E492 -> 0 | E15: ='ريز جاري'!G492 -> 0 | F15: =D15/تسعير!E34+E15 -> #DIV/0!
A16: 12 | C16: خريد اقلام مصرفي | D16: ='ريز جاري'!E114 -> 0 | E16: ='ريز جاري'!G114 -> 0 | F16: =D16/تسعير!E34+E16 -> #DIV/0!
A17: 13 | C17: هزينه حقوق كاركنان اعزامي از مركز | F17: =D17/تسعير!E34+E17 -> #DIV/0!
A18: 14 | F18: =D18/تسعير!E34+E18 -> #DIV/0!
A19: 15 | F19: =D19/تسعير!E34+E19 -> #DIV/0!
A20: 16 | F20: =D20/تسعير!E34+E20 -> #DIV/0!
A21: 17 | F21: =D21/تسعير!E34+E21 -> #DIV/0!
A22: 18 | F22: =D22/تسعير!E34+E22 -> #DIV/0!
A23: 19 | F23: =D23/تسعير!E34+E23 -> #DIV/0!
A24: 20 | F24: =D24/تسعير!E34+E24 -> #DIV/0!
A25: 21 | F25: =D25/تسعير!E34+E25 -> #DIV/0!
A26: 22 | F26: =D26/تسعير!E34+E26 -> #DIV/0!
A27: 23 | F27: =D27/تسعير!E34+E27 -> #DIV/0!
A28: 24 | F28: =D28/تسعير!E34+E28 -> #DIV/0!
A29: 25 | F29: =D29/تسعير!E34+E29 -> #DIV/0!
A30: 26 | F30: =D30/تسعير!E34+E30 -> #DIV/0!
A31: 27 | F31: =D31/تسعير!E34+E31 -> #DIV/0!
A32: 28 | F32: =D32/تسعير!E34+E32 -> #DIV/0!
A33: 29 | F33: =D33/تسعير!E34+E33 -> #DIV/0!
A34: 30 | F34: =D34/تسعير!E34+E34 -> #DIV/0!
A35: جمع هزينه هاي جاري | D35: =SUM(D5:D34) -> 0 | E35: =SUM(E5:E34) -> 0 | F35: =SUM(F5:F34) -> #DIV/0!
A37: تنظيم كننده: | C37: حسابرس اعزامي: | E37: رايزني فرهنگي ج.ا.ا:
A47: ليست كلي هزينه هاي فرهنگي رايزني فرهنگي ج.ا.ايران در
A48: سال 13
A50: رديف | B50: كد برنامه | C50: عنوان برنامه | D50: ارز محل | E50: يورو | F50: جمع به يورو
A51: 1 | C51: برگزاري جشن نوروز | D51: ='ريز فرهنگي'!E30 -> 0 | E51: ='ريز فرهنگي'!G30 -> 0 | F51: =D51/تسعير!E34+E51 -> #DIV/0!
A52: 2 | C52: برگزاري مراسم ارتحال امام | D52: ='ريز فرهنگي'!E72 -> 0 | E52: ='ريز فرهنگي'!G72 -> 0 | F52: =D52/تسعير!E34+E52 -> #DIV/0!
...

Sheet تراز يوروئي و ارزمحل
A2: نمايندگي فرهنگي سفارت ج.ا.ايران در
A3: تراز عمليات مالي حساب هاي يوروئي از تاريخ لغايت ارقام به: يورو
A4: شرح حساب | B4: گردش عمليات مالي | D4: مانده نهايي حساب
B6: بدهكار | C6: بستانكار | D6: بدهكار | E6: بستانكار
A7: بانك:
A8: حساب(جاري1) يورويي به شماره
A9: حساب(جاري2) يورويي به شماره
A10: تنخواه گردان پرداختي:
A11: موجودي صندوق
A12: علي الحساب ها:
A13: يك:علي الحساب(اگراز رايزني طلب داشته باشد)
A14: دو:
A15: سه: پيش پرداخت
A16: وام كاركنان محلي(بدهكار)
A17: حساب سفارت(مانده حساب رايزني نزد سفارت)
A18: حساب تسعير يورو به ارز محل | D18: =تسعير!D34 -> 0
A19: هزينه ها:
A20: هزينه هاي جاري | D20: ='روكش جاري و فرهنگي'!E35-'روكش جاري و فرهنگي'!F17 -> #DIV/0!
A21: هزينه هاي فرهنگي | D21: ='روكش جاري و فرهنگي'!E81 -> 0
A22: هزينه حقوق كاركنان اعزامي از مركز | D22: ='روكش جاري و فرهنگي'!F17 -> #DIV/0!
A23: هزينه(1)
A24: هزينه(2)
A25: حساب دريافتي از سازمان بابت بودجه برنامه اي:
A26: بابت بودجه برنامه اي سال جاري
A27: بابت(1)علي الحساب دريافتي از مركز...
A28: حساب وجوه مصرف نشده سنوات قبل
A29: مانده موجودي نقل از دوره قبل(صندوق+بانك)
A30: دريافتي بابت درآمد
A31: جمع كل: | B31: =SUM(B7:B30) -> 0 | C31: =SUM(C7:C30) -> 0 | D31: =SUM(D7:D30) -> #DIV/0! | E31: =SUM(E7:E30) -> 0
A33: بدين وسيله صحت ارقام در ترازنامه نمايندگي ب شرح فوق از تاريخ لغايت مورد تأئيد است.
A35: حسابرس اعزامي: | C35: رايزني فرهنگي ج.ا.ايران در
A43: نمايندگي فرهنگي سفارت ج.ا.ايران در
A44: تراز عمليات مالي حساب هاي ارز محل از تاريخ لغايت ارقام به :ارز محل
D45: نرخ ميانگين تسعير: | E45: =تسعير!E34 -> #DIV/0!
A46: شرح حساب | B46: گردش عمليات مالي | D46: مانده نهايي حساب
B48: بدهكار | C48: بستانكار | D48: بدهكار | E48: بستانكار
A49: بانك:
A50: حساب(جاري1) ارز محل به شماره
A51: حساب(جاري2) ارز محل به شماره
A52: تنخواه گردان پرداختي:
...

Sheet تراز تلفيقي
A1: نمايندگي فرهنگي سفارت ج.ا.ايران در
A2: تراز عمليات تلفيقي (حساب ارز محل و يورو)
A3: از تاريخ15/15/91لغايت15/15/91نرخ ميانگين تسعير: | C3: =تسعير!E34 -> #DIV/0!
A4: شرح حساب | B4: حساب هاي يوروئي | D4: معادل يورو حساب هاي ارز محل | F4: مانده نهايي به يورو
B5: بدهكار | C5: بستانكار | D5: بدهكار | E5: بستانكار | F5: بدهكار | G5: بستانكار
A6: بانك:
A7: حساب يوروئي(1) به شماره | B7: ='تراز يوروئي و ارزمحل'!D8 -> 0 | F7: =B7 -> 0
A8: حساب يوروئي(2) به شماره | B8: ='تراز يوروئي و ارزمحل'!D9 -> 0 | F8: =B8 -> 0
A9: حساب ارز محل(1) به شماره | D9: ='تراز يوروئي و ارزمحل'!D50/تسعير!E34 -> #DIV/0! | F9: =D9 -> #DIV/0!
A10: حساب ارز محل(2) به شماره | D10: ='تراز يوروئي و ارزمحل'!D51/تسعير!E34 -> #DIV/0! | F10: =D10 -> #DIV/0!
A11: تنخواه گردان پرداخت:
A12: موجودي صندوق | B12: ='تراز يوروئي و ارزمحل'!D11 -> 0 | C12: ='تراز يوروئي و ارزمحل'!E11 -> 0 | D12: ='تراز يوروئي و ارزمحل'!D53/تسعير!E34 -> #DIV/0! | E12: ='تراز يوروئي و ارزمحل'!E53/'تراز يوروئي و ارزمحل'!E45 -> #DIV/0! | F12: =D12+B12-E12-C12 -> #DIV/0!
A13: علي الحساب ها:
A14: علي الحساب يك(اگر از رايزني طلب داشته باشد) | C14: ='تراز يوروئي و ارزمحل'!E13 -> 0 | E14: ='تراز يوروئي و ارزمحل'!E55/تسعير!E34 -> #DIV/0! | G14: =E14+C14 -> #DIV/0!
A15: علي الحساب دو | B15: ='تراز يوروئي و ارزمحل'!D14 -> 0 | D15: ='تراز يوروئي و ارزمحل'!D56/تسعير!E34 -> #DIV/0! | F15: =D15+B15 -> #DIV/0!
A16: علي الحساب سه | B16: ='تراز يوروئي و ارزمحل'!D15 -> 0 | D16: ='تراز يوروئي و ارزمحل'!D57/تسعير!E34 -> #DIV/0! | F16: =D16+B16 -> #DIV/0!
A17: وام كاركنان محلي | B17: ='تراز يوروئي و ارزمحل'!D16 -> 0 | D17: ='تراز يوروئي و ارزمحل'!D58/تسعير!E34 -> #DIV/0! | F17: =D17+B17 -> #DIV/0!
A18: حساب سفارت | B18: ='تراز يوروئي و ارزمحل'!D17 -> 0 | D18: ='تراز يوروئي و ارزمحل'!D59/تسعير!E34 -> #DIV/0! | F18: =D18+B18 -> #DIV/0!
A19: حساب تسعير يورو به ارز محل | B19: ='تراز يوروئي و ارزمحل'!D18 -> 0 | F19: =B19 -> 0
A20: حساب دريافتي ناشي از تسعير يورو به ارز محل | E20: ='تراز يوروئي و ارزمحل'!E67/تسعير!E34 -> #DIV/0! | G20: =E20 -> #DIV/0!
A21: هزينه ها:
A22: هزينه هاي جاري | B22: ='تراز يوروئي و ارزمحل'!D20 -> #DIV/0! | D22: ='تراز يوروئي و ارزمحل'!D61/تسعير!E34 -> #DIV/0! | F22: =D22+B22 -> #DIV/0!
A23: هزينه هاي فرهنگي | B23: ='تراز يوروئي و ارزمحل'!D21 -> 0 | D23: ='تراز يوروئي و ارزمحل'!D62/تسعير!E34 -> #DIV/0! | F23: =D23+B23 -> #DIV/0!
A24: هزينه حقوق كاركنان اعزامي از مركز | B24: ='تراز يوروئي و ارزمحل'!D22 -> #DIV/0! | F24: =B24 -> #DIV/0!
A25: هزينه يك | B25: ='تراز يوروئي و ارزمحل'!D23 -> 0 | D25: ='تراز يوروئي و ارزمحل'!D63/تسعير!E34 -> #DIV/0! | F25: =D25+B25 -> #DIV/0!
A26: هزينه دو | B26: ='تراز يوروئي و ارزمحل'!D24 -> 0 | D26: ='تراز يوروئي و ارزمحل'!D64/تسعير!E34 -> #DIV/0! | F26: =D26+B26 -> #DIV/0!
A27: هزينه خريد خودرو | F27: =D27+B27 -> 0
A28: هزينه هاي واخواهي شده | F28: =D28+B28 -> 0
A29: حساب دريافتي از سازمان بابت بودجه برنامه اي
A30: بابت بودجه برنامه اي سال جاري | C30: ='تراز يوروئي و ارزمحل'!E26 -> 0 | G30: =C30 -> 0
A31: بابت(1) بودجه ساير ادارات | C31: ='تراز يوروئي و ارزمحل'!E27 -> 0 | G31: =C31 -> 0
A32: حساب وجوه مصرف نشده سنوات قبل
A33: مانده موجودي نقل از دوره قبل(صندوق+بانك) | C33: ='تراز يوروئي و ارزمحل'!E29 -> 0 | E33: ='تراز يوروئي و ارزمحل'!E66/تسعير!E34 -> #DIV/0! | G33: =E33+C33 -> #DIV/0!
A34: دريافتي بابت درآمد | C34: ='تراز يوروئي و ارزمحل'!E30 -> 0 | E34: ='تراز يوروئي و ارزمحل'!E68/تسعير!E34 -> #DIV/0! | G34: =E34+C34 -> #DIV/0!
A35: جمع كل | B35: =SUM(B6:B34) -> #DIV/0! | C35: =SUM(C6:C34) -> 0 | D35: =SUM(D6:D34) -> #DIV/0! | E35: =SUM(E6:E34) -> #DIV/0! | F35: =SUM(F6:F34) -> #DIV/0! | G35: =SUM(G6:G34) -> #DIV/0!
A36: بدين وسيله صحت ارقام در ترازنامه نمايندگي به شرح فوق از تاريخ لغايت با نرخ ميانگين تسعير:
A37: برابر با يك يورو مورد تأئيد است.
A38: حسابرس اعزامي | D38: رايزني فرهنگي ج.ا.ايران در

Sheet ریزحقوق کارکنان محلی
A1: حقوق،بازخريدي و...كاركنان بومي کد برنامه: فروردین سال
A2: حقوق،بازخريدي و...كاركنان بومي کد برنامه: اردیبهست سال
A3: حقوق،بازخريدي و...كاركنان بومي کد برنامه: خرداد سال
A4: حقوق،بازخريدي و...كاركنان بومي کد برنامه: تیر سال
A5: حقوق،بازخريدي و...كاركنان بومي کد برنامه: مرداد سال
A6: حقوق،بازخريدي و...كاركنان بومي کد برنامه: شهریور سال
A7: حقوق،بازخريدي و...كاركنان بومي کد برنامه: مهر سال
A8: حقوق،بازخريدي و...كاركنان بومي کد برنامه: آبان سال
A9: حقوق،بازخريدي و...كاركنان بومي کد برنامه: آذر سال
A10: حقوق،بازخريدي و...كاركنان بومي کد برنامه: دی سال
A11: حقوق،بازخريدي و...كاركنان بومي کد برنامه: بهمن سال
A12: حقوق،بازخريدي و...كاركنان بومي کد برنامه: اسفند سال
A32: نمایندگی فرهنگی ج.ا.ایران در
A33: حقوق،بازخريدي و...كاركنان بومي کد برنامه: فروردین سال | G33: نرخ تسعیر: | H33: =تسعير!E34 -> #DIV/0!
A34: ردیف | B34: نام و نام خانوادگی | C34: شغل | D34: حقوق ماهانه به یورو | E34: حقوق ماهانه به ارز محل | F34: ساعت اضافه کار | G34: مبلغ اضافه کار به یورو | H34: جمع کل پرداختی به یورو | I34: توضیحات
A35: 1 | H35: =D35+(E35/H33)+G35 -> #DIV/0!
A36: 2 | H36: =D36+E36/H33+G36 -> #DIV/0!
A37: 3 | H37: =D37+E37/H33+G37 -> #DIV/0!
A38: 4 | H38: =D38+E38/H33+G38 -> #DIV/0!
A39: 5 | H39: =D39+E39/H33+G39 -> #DIV/0!
A40: 6 | H40: =D40+E40/H33+G40 -> #DIV/0!
A41: 7 | H41: =D41+E41/H33+G41 -> #DIV/0!
A42: 8 | H42: =D42+E42/H33+G42 -> #DIV/0!
A43: 9 | H43: =D43+E43/H33+G43 -> #DIV/0!
A44: 10 | H44: =D44+E44/H33+G44 -> #DIV/0!
A45: 11 | H45: =D45+E45/H33+G45 -> #DIV/0!
A46: 12 | H46: =D46+E46/H33+G46 -> #DIV/0!
A47: جمع کل: | D47: =SUM(D35:D46) -> 0 | E47: =SUM(E35:E46) -> 0 | F47: =SUM(F35:F46) -> 0 | G47: =SUM(G35:G46) -> 0 | H47: =SUM(H35:H46) -> #DIV/0!
A48: بدینوسیله گواهی میشود مبلغ یورو بابت حقوق فروردین ماه و مبلغ یورو بابت اضافه کاری جمعآ به مبلغ یورو به تعداد نفر از کارکنان محلی رایزنی فرهنگی ج. ا.ایران در کشور از محل بودجه برنامه مصوب پرداخت گردیده است. صحن مندرجات مورد تأئید می باشد.
A51: کارشناس فرهنگی | G51: مهر و امضاء رایزنی فرهنگی
A58: نمایندگی فرهنگی ج.ا.ایران در
A59: حقوق،بازخريدي و...كاركنان بومي کد برنامه: اردیبهشت سال | G59: نرخ تسعیر: | H59: =تسعير!E34 -> #DIV/0!
A60: ردیف | B60: نام و نام خانوادگی | C60: شغل | D60: حقوق ماهانه به یورو | E60: حقوق ماهانه به ارز محل | F60: ساعت اضافه کار | G60: مبلغ اضافه کار به یورو | H60: جمع کل پرداختی به یورو | I60: توضیحات
A61: 1 | H61: =D61+E61/H59+G61 -> #DIV/0!
A62: 2 | H62: =D62+E62/H59+G62 -> #DIV/0!
A63: 3 | H63: =D63+E63/H59+G63 -> #DIV/0!
A64: 4 | H64: =D64+E64/H59+G64 -> #DIV/0!
A65: 5 | H65: =D65+E65/H59+G65 -> #DIV/0!
A66: 6 | H66: =D66+E66/H59+G66 -> #DIV/0!
A67: 7 | H67: =D67+E67/H59+G67 -> #DIV/0!
...

Sheet روکش حقوق محلی
A1: نمایندگی فرهنگی سفارت ج.ا.ایران در
A2: روکش لیست هزینه های حقوق بازخریدی و پاداش کارکنان محلی
A3: کد برنامه مصوب: | D3: نرخ تسعیر: | E3: =تسعير!E34 -> #DIV/0!
A4: ردیف | B4: شرح هزینه | C4: ارز محل | D4: اضافه کاری یورو | E4: حقوق یورو | F4: جمع کل به یورو
A5: 1 | B5: حقوق و اضافه کاری فروردین ماه سال | C5: ='ریزحقوق کارکنان محلی'!E47 -> 0 | D5: ='ریزحقوق کارکنان محلی'!G47 -> 0 | E5: ='ریزحقوق کارکنان محلی'!D47 -> 0 | F5: ='ریزحقوق کارکنان محلی'!H47 -> #DIV/0!
A6: 2 | B6: حقوق و اضافه کاری اردیبهشت ماه سال | C6: ='ریزحقوق کارکنان محلی'!E73 -> 0 | D6: ='ریزحقوق کارکنان محلی'!G73 -> 0 | E6: ='ریزحقوق کارکنان محلی'!D73 -> 0 | F6: ='ریزحقوق کارکنان محلی'!H73 -> #DIV/0!
A7: 3 | B7: حقوق و اضافه کاری خرداد ماه سال | C7: ='ریزحقوق کارکنان محلی'!E99 -> 0 | D7: ='ریزحقوق کارکنان محلی'!G99 -> 0 | E7: ='ریزحقوق کارکنان محلی'!D99 -> 0 | F7: ='ریزحقوق کارکنان محلی'!H99 -> #DIV/0!
A8: 4 | B8: حقوق و اضافه کاری تیر ماه سال | C8: ='ریزحقوق کارکنان محلی'!E125 -> 0 | D8: ='ریزحقوق کارکنان محلی'!G125 -> 0 | E8: ='ریزحقوق کارکنان محلی'!D125 -> 0 | F8: ='ریزحقوق کارکنان محلی'!H125 -> #DIV/0!
A9: 5 | B9: حقوق و اضافه کاری مرداد ماه سال | C9: ='ریزحقوق کارکنان محلی'!E151 -> 0 | D9: ='ریزحقوق کارکنان محلی'!G151 -> 0 | E9: ='ریزحقوق کارکنان محلی'!D151 -> 0 | F9: ='ریزحقوق کارکنان محلی'!H151 -> #DIV/0!
A10: 6 | B10: حقوق و اضافه کاری شهریور ماه سال | C10: ='ریزحقوق کارکنان محلی'!E177 -> 0 | D10: ='ریزحقوق کارکنان محلی'!G177 -> 0 | E10: ='ریزحقوق کارکنان محلی'!D177 -> 0 | F10: ='ریزحقوق کارکنان محلی'!H177 -> #DIV/0!
A11: 7 | B11: حقوق و اضافه کاری مهر ماه سال | C11: ='ریزحقوق کارکنان محلی'!E203 -> 0 | D11: ='ریزحقوق کارکنان محلی'!G203 -> 0 | E11: ='ریزحقوق کارکنان محلی'!D203 -> 0 | F11: ='ریزحقوق کارکنان محلی'!H203 -> #DIV/0!
A12: 8 | B12: حقوق و اضافه کاری آبان ماه سال | C12: ='ریزحقوق کارکنان محلی'!E229 -> 0 | D12: ='ریزحقوق کارکنان محلی'!G229 -> 0 | E12: ='ریزحقوق کارکنان محلی'!D229 -> 0 | F12: ='ریزحقوق کارکنان محلی'!H229 -> #DIV/0!
A13: 9 | B13: حقوق و اضافه کاری آذر ماه سال | C13: ='ریزحقوق کارکنان محلی'!E255 -> 0 | D13: ='ریزحقوق کارکنان محلی'!G255 -> 0 | E13: ='ریزحقوق کارکنان محلی'!D255 -> 0 | F13: ='ریزحقوق کارکنان محلی'!H255 -> #DIV/0!
A14: 10 | B14: حقوق و اضافه کاری دی ماه سال | C14: ='ریزحقوق کارکنان محلی'!E281 -> 0 | D14: ='ریزحقوق کارکنان محلی'!G281 -> 0 | E14: ='ریزحقوق کارکنان محلی'!D281 -> 0 | F14: ='ریزحقوق کارکنان محلی'!H281 -> #DIV/0!
A15: 11 | B15: حقوق و اضافه کاری بهمن ماه سال | C15: ='ریزحقوق کارکنان محلی'!E307 -> 0 | D15: ='ریزحقوق کارکنان محلی'!G307 -> 0 | E15: ='ریزحقوق کارکنان محلی'!D307 -> 0 | F15: ='ریزحقوق کارکنان محلی'!H307 -> #DIV/0!
A16: 12 | B16: حقوق و اضافه کاری اسفند ماه سال | C16: ='ریزحقوق کارکنان محلی'!E333 -> 0 | D16: ='ریزحقوق کارکنان محلی'!G333 -> 0 | E16: ='ریزحقوق کارکنان محلی'!D333 -> 0 | F16: ='ریزحقوق کارکنان محلی'!H333 -> #DIV/0!
A17: 13 | B17: هزینه یک:
A18: 14 | B18: هزینه دو:
A19: 15 | B19: هزینه سه:
A20: 16 | B20: هزینه چهار:
A21: 17 | B21: هزینه پنج:
A22: 18
A23: 19
A24: 20
A25: جمع کل: | C25: =SUM(C5:C24) -> 0 | D25: =SUM(D5:D24) -> 0 | E25: =SUM(E5:E24) -> 0 | F25: =SUM(F5:F24) -> #DIV/0!
A26: جمع یوروئی | D26: =E25+D25 -> 0 | F26: =F25 -> #DIV/0!
A27: بدینوسیله گواهی میشود مبلغ ارز محل ( ) با نرخ تسعیر برابر یورو و احتساب مبلغ هزینه یورویی جمعأ به مبلغ یورو از تاریخ لغایت از محل بودجه برنامه مصوب هزینه گردیه است.
A29: حسابرس اعزامی | D29: رایزنی فرهنگی

Sheet فهرست وجوه ارسالي
A1: فهرست وجوه ارسالي از سازمان فرهنگ و ارتباطات اسلامي
A2: نمايندگي فرهنگي سفارت ج.ا.ايران در ارمنستان
A3: از تاريخ 90/08/26 لغايت 90/12/28
G4: ارقام: به يورو
A5: رديف | B5: شرح برنامه | C5: شماره سند | D5: شماره حواله | E5: تاريخ حواله | F5: بودجه ارسالي | G5: بودجه واريز شده به حساب | H5: كارمزد بانكي
A6: 1 | B6: تغيير و تحول | C6: 753 | D6: 1390/8/26 | F6: 64077
A7: 2 | B7: علي الحساب ابتداي ماموريت آقاي | C7: 338 | D7: 212878 | E7: 1390/6/12 | F7: 12000 | G7: 12000
A8: 3 | B8: بابت برنامه فعاليتهاي قرآني | C8: 407 | D8: 84/23893 | E8: 1390/6/16 | F8: 2000 | G8: 2000 | H8: =F8-G8 -> 0
A9: 4 | B9: علي الحساب ابتداي ماموريت آقاي شيراوند طي چك 212555 | C9: 661 | D9: 212555 | E9: 1390/8/21 | F9: 18000 | G9: 18000 | H9: =F9-G9 -> 0
A10: 5 | B10: حواله بابت بليط آقاي حسن معافي مدني | C10: 680 | D10: 84/24369 | E10: 1390/9/2 | F10: 863 | G10: 863 | H10: =F10-G10 -> 0
A11: 6 | B11: حواله بابت حقوق آقاي كاكا و شكيبا و هادي حسني | C11: 724 | D11: 84/24485 | E11: 1390/9/13 | F11: 23183 | G11: 23183 | H11: =F11-G11 -> 0
A12: 7 | B12: حواله بابت معوقه حقوق آقاي محمد رضا | C12: 779 | D12: 84/24576 | E12: 1390/9/30 | F12: 4143 | G12: 4143 | H12: =F12-G12 -> 0
A13: 8 | B13: حواله بابت بودجه جاري ؛فرهنگي و خريد خودرو(17660 يورو) | C13: 832 | D13: 84/24678 | E13: 1390/10/13 | F13: 50846 | G13: 50846 | H13: =F13-G13 -> 0
A14: 9 | B14: حواله بابت حقوق آقاي به همراه معوقه و حقوق حسني(6000-) | C14: 994 | D14: 84/24850 | E14: 1390/11/10 | F14: 19863 | G14: 19863 | H14: =F14-G14 -> 0
A15: 10 | B15: حواله بابت جاري فرهنگي (سه ماهه چهارم) | C15: 1212 | D15: 84/25187 | E15: 1390/12/28 | F15: 51000 | G15: 51000 | H15: =F15-G15 -> 0
A16: 11 | B16: حواله بابت تاسيس اتاق ايرانشناسي و خريد خودرو(5000 يورو) | C16: 1234 | D16: 84/25241 | E16: 1391/1/8 | F16: 15000 | G16: 15000 | H16: =F16-G16 -> 0
A17: 12 | B17: حواله بابت حقوق آقاي مهران شيرآوند با كسر 7000 يورو | C17: 1239 | D17: 84/25488 | E17: 1391/1/8 | F17: 9206 | G17: 9206 | H17: =F17-G17 -> 0
A18: 13 | B18: حواله بابت راه اندازي مركز اطلاع رساني و كتابخانه اسناد | C18: 1254 | D18: 84/25285 | E18: 1391/1/8 | F18: 5000 | G18: 5000 | H18: =F18-G18 -> 0
A19: 14 | B19: حواله بابت بازخريدي خانم آرمينوس ميناس | C19: 1320 | D19: 84/25387 | E19: 1391/1/30 | F19: 1200 | G19: 1200 | H19: =F19-G19 -> 0
A20: جمع كل | F20: =SUM(F6:F19) -> 276381 | G20: =SUM(G6:G19) -> 212304 | H20: =SUM(H6:H19) -> 0
A21: بدينوسيله گواهي مي شود حواله هاي فوق الذكر بابت بودجه جاري فرهنگي واريزي با صورتحساب و اعلاميه هاي بانكي حساب هاي بانكي نمايندگي تطبيق داده شده و
A22: وجوه واريزي به حساب بانكي به شرح فوق مي باشد .مراتب مورد تاييد است.
A24: حسابرس اعزامي از مركز | F24: رايزني فرهنگي ج.ا. ايران در ارمنستان

Sheet هزينه و انحراف
A1: نمايندگي فرهنگي ج.ا.ايران در
A3: رديف | B3: موضوع برنامه | C3: مصوب | D3: تخصيص | E3: دريافتي | F3: هزينه | G3: انحراف | H3: توضيحات
A4: 1
A5: 2
A6: 3
A7: 4
A8: 5
A9: 6
A10: 7
A11: 8
A12: 9
A13: 10
A14: 11
A15: 12
... A18: 15
A19: جمع
A21: حسابرس اعزامي: | F21: رايزني فرهنگي ج.ا.ايران:

Sheet هزينه و انحراف 2
A1: صورت خلاصه هزینه های جاری نمایندگی فرهنگی جمهوری اسلامی ایران در تركمنستان از تاریخ 1392/01/01 لغایت 1392/12/28
A4: ردیف | B4: کد برنامه | C4: عنوان هزینه | D4: بودجه | E4: هزینه | F4: معادل | G4: هزینه | H4: جمع عملکرد | I4: بودجه | J4: انحراف | K4: تعداد سند به برگ
D5: مصوب | E5: به ارز محل | F5: یوروئی هزینه | G5: به یورو | H5: هزینه | I5: تخصیص | J5: هزینه
A6: 1 | B6: 921211515 | C6: حقوق کارکنان محلی بومی رایزنی | D6: 0 | E6: 0 | F6: =E6/E28 -> 0 | G6: 6345.5 | H6: =F6+G6 -> 6345.5 | I6: 1000 | J6: =I6-H6 -> -5345.5 | K6: 9
A7: 2 | B7: 9212115144 | C7: هزینه های پیش بینی نشده در امور فرهنگی و جاری | D7: 0 | E7: 3539.25 | F7: =E7/E28 -> 1497.7782 | G7: 2200 | H7: =F7+G7 -> 3697.7782 | I7: 1000 | J7: =I7-H7 -> -2697.7782 | K7: 72
A8: 3 | B8: 9212115145 | C8: هزينه های تعمير و نگهداري اماكن و وسايل اداري | D8: 0 | E8: 982.83 | F8: =E8/E28 -> 415.92467 | G8: 0 | H8: =F8+G8 -> 415.92467 | I8: 3000 | J8: =I8-H8 -> 2584.0753 | K8: 2
A9: 4 | B9: 9212115146 | C9: هزینه های تعمير و نگهداري خودرو | D9: 0 | E9: 3805.34 | F9: =E9/E28 -> 1610.3851 | G9: 0 | H9: =F9+G9 -> 1610.3851 | I9: 1500 | J9: =I9-H9 -> -110.3851 | K9: 2
A10: 5 | B10: 9212115147 | C10: هزينه آب؛برق؛گاز؛وسایر سوختها | D10: 0 | E10: 3481.6 | F10: =E10/E28 -> 1473.3813 | G10: 0 | H10: =F10+G10 -> 1473.3813 | I10: 552 | J10: =I10-H10 -> -921.38129 | K10: 2
A11: 6 | B11: 9212115148 | C11: هزینه تلفن ؛ فکس ؛ واينترنت | D11: 0 | E11: 5061.33 | F11: =E11/E28 -> 2141.9086 | G11: 0 | H11: =F11+G11 -> 2141.9086 | I11: 255 | J11: =I11-H11 -> -1886.9086 | K11: 2
A12: 7 | B12: 9212115149 | C12: هزینه های بانکی و پست | D12: 0 | E12: 219 | F12: =E12/E28 -> 92.678798 | G12: 0 | H12: =F12+G12 -> 92.678798 | I12: 266 | J12: =I12-H12 -> 173.3212 | K12: 5
A13: 8 | B13: 9212115150 | C13: خرید اقلام مصرفی و پذیرائی | D13: 0 | E13: 1157.81 | F13: =E13/E28 -> 489.97461 | G13: 0 | H13: =F13+G13 -> 489.97461 | I13: 2 | J13: =I13-H13 -> -487.97461 | K13: 22
A14: 9 | B14: 9212115151 | C14: حمل نقل و ارتباطات | D14: 0 | E14: 0 | F14: =E14/E28 -> 0 | G14: 0 | H14: 0 | I14: 66 | J14: =I14-H14 -> 66 | K14: 2
A15: 10 | B15: 9212115154 | C15: کمک هزینه درمان وبیمه کارکنان | D15: 0 | E15: 7254.14 | F15: =E15/E28 -> 3069.8857 | G15: 0 | H15: =F15+G15 -> 3069.8857 | I15: 6 | J15: =I15-H15 -> -3063.8857 | K15: 25
A16: 11 | D16: 0 | E16: 0 | F16: =E16/E28 -> 0 | G16: 0 | H16: =G16+F16 -> 0 | I16: 26 | J16: =I16-H16 -> 26 | K16: 5
A17: 12 | D17: 0 | E17: 0 | F17: =E17/E28 -> 0 | G17: 0 | H17: =G17+F17 -> 0 | I17: =G17+H17 -> 0 | J17: =I17-H17 -> 0 | K17: 5
A18: 13 | D18: 0 | E18: 0 | F18: =E18/E28 -> 0 | G18: 0 | H18: =G18+F18 -> 0 | I18: 6 | J18: =I18-H18 -> 6 | K18: 5
A19: 14 | D19: 0 | E19: 0 | F19: =E19/E28 -> 0 | G19: 0 | H19: =G19+F19 -> 0 | I19: 26 | J19: =I19-H19 -> 26 | K19: 5
A20: 15 | D20: 0 | E20: 0 | F20: =E20/E28 -> 0 | G20: 0 | H20: =G20+F20 -> 0 | I20: 2 | J20: =I20-H20 -> 2 | K20: 55
A21: 16 | D21: 0 | E21: 0 | F21: =E21/E28 -> 0 | H21: =G21+F21 -> 0 | I21: 6 | J21: =I21-H21 -> 6 | K21: 5
A22: 17 | B22: 9212115155 | C22: کمک هزینه تحصیلی فرزندان کارکنان اعزامی از مرکز | D22: 0 | E22: 0 | F22: =E22/E28 -> 0 | G22: 770 | H22: =F22+G22 -> 770 | I22: 62 | J22: =I22-H22 -> -708 | K22: 25
A23: 18 | B23: 9212115157 | C23: حقوق اعزامی از مرکز | D23: 0 | E23: 0 | F23: =E23/E28 -> 0 | G23: 10992 | H23: =F23+G23 -> 10992 | I23: 6 | J23: =I23-H23 -> -10986 | K23: 41
A24: 19 | B24: 9212115157 | C24: علی الحساب حقوق کارکنان محلی | D24: 0 | E24: 0 | F24: =E24/E28 -> 0 | G24: 600 | H24: =F24+G24 -> 600 | I24: 66 | J24: =I24-H24 -> -534 | K24: 12
A25: 20 | B25: 0 | C25: هزینه اجاره ساختمان مرکز آموزش | D25: 0 | E25: 18138 | F25: =E25/E28 -> 7675.8358 | G25: 0 | H25: =F25+G25 -> 7675.8358 | I25: 26 | J25: =I25-H25 -> -7649.8358 | K25: 14
A26: 21 | B26: 0 | C26: علی الحساب حقوق کارکنان اعزامی | D26: 0 | E26: 0 | F26: =E26/E28 -> 0 | G26: 3000 | H26: =F26+G26 -> 3000 | I26: 2 | J26: =I26-H26 -> -2998 | K26: 54
A27: جمع کل هزینه های جاری و حقوق | D27: =SUM(D6:D25) -> 0 | E27: =SUM(E6:E25) -> 43639.3 | F27: =SUM(F6:F25) -> 18467.753 | G27: =SUM(G6:G25) -> 20907.5 | H27: =SUM(H6:H25) -> 39375.253 | I27: =SUM(I6:I25) -> 7873 | J27: =SUM(J6:J25) -> -31502.253 | K27: =SUM(K6:K26) -> 369
C28: سعيد حقاني | D28: تسعير: | E28: 2.363 | G28: ابوالحسن خلج منفرد
C29: حسابرس اعزامي | G29: رایزن فرهنگی جمهوری اسلامی ایران در تركمنستان
