Workbook

Sheet تسعير
A1: رايزني فرهنگي جمهوري اسلامي ايران در : ترکمنستان | I1: رايزني فرهنگي جمهوري اسلامي ايران در : ترکمنستان
A2: از تاریخ 1391/7/28 لغایت 91/12/28 | I2: از تاریخ 1391/7/28 لغایت 91/12/28
A4: رديف | B4: تاريخ | C4: شماره چك/نقدي | D4: مبلغ يورو | E4: نرخ تسعير | F4: تبديلي به: منات | G4: ملاحضات | I4: ردیف | J4: تاریخ | K4: یورو | L4: تسعیر دلار | M4: تبدیل شده به دلار | N4: تسعیر منات | O4: تبدیل شده به منات
A5: 1 | E5: =F5/D5 -> #DIV/0! | I5: 1 | K5: 2606.97 | L5: =M5/K5 -> 1.2900033 | M5: 3363 | N5: =O5/M5 -> 2.86 | O5: 9618.18
A6: 2 | B6: شش ماه دوم | C6: آزاد | D6: 2031.44 | E6: =F6/D6 -> 3.6889891 | F6: 7493.96 | G6: بدون رسید و یا فیش | I6: 2
A7: 3 | B7: شش ماه دوم | C7: آزاد | D7: 2031.44 | E7: =F7/D7 -> 3.6889891 | F7: 7493.96 | G7: بدون رسید و یا فیش | I7: 3
A8: 4 | B8: شش ماه دوم | C8: آزاد | D8: 2031.44 | E8: =F8/D8 -> 3.6889891 | F8: 7493.96 | G8: بدون رسید و یا فیش | I8: 4
A9: 5 | B9: شش ماه دوم | C9: آزاد | D9: 2031.44 | E9: =F9/D9 -> 3.6889891 | F9: 7493.96 | G9: بدون رسید و یا فیش | I9: 5
A10: 6 | B10: شش ماه دوم | C10: آزاد | D10: 2031.44 | E10: =F10/D10 -> 3.6889891 | F10: 7493.96 | G10: بدون رسید و یا فیش | I10: 6
A11: 7 | B11: شش ماه دوم | C11: آزاد | D11: 2031.44 | E11: =F11/D11 -> 3.6889891 | F11: 7493.96 | G11: بدون رسید و یا فیش | I11: 7
A12: 8 | B12: شش ماه دوم | C12: آزاد | D12: 2031.44 | E12: =F12/D12 -> 3.6889891 | F12: 7493.96 | G12: بدون رسید و یا فیش | I12: 8
A13: 9 | B13: شش ماه دوم | C13: آزاد | D13: 2031.44 | E13: =F13/D13 -> 3.6889891 | F13: 7493.96 | G13: بدون رسید و یا فیش | I13: 9
A14: 10 | B14: شش ماه دوم | C14: آزاد | D14: 2031.44 | E14: =F14/D14 -> 3.6889891 | F14: 7493.96 | G14: بدون رسید و یا فیش | I14: 10
A15: 11 | B15: شش ماه دوم | C15: آزاد | D15: 2059.5 | E15: =F15/D15 -> 3.6890022 | F15: 7597.5 | G15: بدون رسید و یا فیش | I15: 11
A16: 12 | I16: 12
A17: 13 | I17: 13
A18: 14 | I18: 14
A19: 15 | I19: 15
A20: 16 | I20: 16
A21: 17 | I21: 17
A22: 18 | I22: 18
A23: 19 | I23: 19
A24: 20 | I24: 20
A25: 21 | I25: 21
A26: 22 | I26: 22
A27: 23 | I27: 23
... A33: 29 | I33: 29
A34: جمع كل | D34: =SUM(D5:D33) -> 20342.46 | E34: =F34/D34 -> 3.6889904 | F34: =SUM(F5:F33) -> 75043.14 | I34: جمع کل | K34: =SUM(K5:K33) -> 2606.97 | L34: =M34/K34 -> 1.2900033 | M34: =SUM(M5:M33) -> 3363 | N34: =O34/M34 -> 2.86 | O34: =SUM(O5:O33) -> 9618.18
A35: مصرف اين دوره حسب فهرست هزينه ها: | F35: ='روكش جاري و فرهنگي'!D81+'روكش جاري و فرهنگي'!D35 -> 75043.14 | K35: 9618.18/2607=3.689 رقم تسعیر منات به یورو
A36: مانده موجودي قابل انتقال به دوره بعد: | D36: =F36/E36 -> 0 | E36: =F34/D34 -> 3.6889904 | F36: =F34-F35 -> 0
A38: تنظيم كننده: | D38: حسابرس اعزامي: | E38: سعید حقانی | F38: رايزني فرهنگي ج .ا.ا: آقای اسماعیل زاده | I38: تنظيم كننده: | L38: حسابرس اعزامي: | M38: سعید حقانی | N38: رايزن فرهنگي ج .ا.ا: آقای اسماعیل زاده
A41: رايزني فرهنگي جمهوري اسلامي ايران در : ترکمنستان
A42: از تاریخ 1391/7/28 لغایت 91/12/28
A44: رديف | B44: تاريخ | C44: شماره چك/نقدي | D44: مبلغ يورو | E44: نرخ تسعير | F44: تبديلي به: دلار | G44: ملاحضات
A45: 1 | D45: 2606.97 | E45: =F45/D45 -> 1.2900033 | F45: 3363
A46: 2
A47: 3
A48: 4
A49: 5
A50: 6
...

Sheet ريز جاري
A1: رايزني فرهنگي ج.ا.ايران در:ترکمنستان | J1: هزينه بانكي(كارمزد)
A2: از تاریخ 1391/7/28 لغایت 91/12/28 | J2: حقوق،بازخريدي و...كاركنان بومي
A3: هزينه جاري:بانكي(كارمزد) | F3: نرخ تسعير: | G3: =تسعير!E34 -> 3.6889904 | J3: خريد اقلام مصرفي و پذیرائی
A4: رديف | B4: تارخ سند | C4: شرح | D4: سند | E4: ارز محل | F4: معادل به يورو | G4: يورو | H4: جمع به يورو | J4: هزينه آب برق گاز و ساير سوخت ها
A5: 1 | F5: =E5/G3 -> 0 | H5: =G5+F5 -> 0 | J5: تعمير و نگهداري خودرو
A6: 2 | F6: =E6/G3 -> 0 | H6: =G6+F6 -> 0 | J6: ترميم و نگهداري جزئي ساختمان
A7: 3 | F7: =E7/G3 -> 0 | H7: =G7+F7 -> 0 | J7: حمل و نقل و ارتباطات
A8: 4 | F8: =E8/G3 -> 0 | H8: =G8+F8 -> 0 | J8: تلفن،فاكس و اينترنت
A9: 5 | F9: =E9/G3 -> 0 | H9: =G9+F9 -> 0 | J9: کمک هزینه تحصیلی فرزندان
A10: 6 | F10: =E10/G3 -> 0 | H10: =G10+F10 -> 0 | J10: كمك هزينه درمان و بيمه كاركنان
A11: 7 | F11: =E11/G3 -> 0 | H11: =G11+F11 -> 0 | J11: هزينه هاي خارج از مصوب و تخصيص
A12: 8 | F12: =E12/G3 -> 0 | H12: =G12+F12 -> 0 | J12: هزينه هاي پيش بيني نشده
A13: 9 | F13: =E13/G3 -> 0 | H13: =G13+F13 -> 0
A14: 10 | F14: =E14/G3 -> 0 | H14: =G14+F14 -> 0
A15: 11 | F15: =E15/G3 -> 0 | H15: =G15+F15 -> 0
A16: 12 | F16: =E16/G3 -> 0 | H16: =G16+F16 -> 0
A17: 13 | F17: =E17/G3 -> 0 | H17: =G17+F17 -> 0
A18: 14 | F18: =E18/G3 -> 0 | H18: =G18+F18 -> 0
A19: 15 | F19: =E19/G3 -> 0 | H19: =G19+F19 -> 0
A20: 16 | F20: =E20/G3 -> 0 | H20: =G20+F20 -> 0
A21: 17 | F21: =E21/G3 -> 0 | H21: =G21+F21 -> 0
A22: 18 | F22: =E22/G3 -> 0 | H22: =G22+F22 -> 0
A23: 19 | F23: =E23/G3 -> 0 | H23: =G23+F23 -> 0
A24: 20 | F24: =E24/G3 -> 0 | H24: =G24+F24 -> 0
A25: 21 | F25: =E25/G3 -> 0 | H25: =G25+F25 -> 0
A26: 22 | F26: =E26/G3 -> 0 | H26: =G26+F26 -> 0
A27: 23 | F27: =E27/G3 -> 0 | H27: =G27+F27 -> 0
A28: 24 | F28: =E28/G3 -> 0 | H28: =G28+F28 -> 0
A29: 25 | F29: =E29/G3 -> 0 | H29: =G29+F29 -> 0
A30: جمع كل | E30: =SUM(E5:E29) -> 0 | F30: =E30/G3 -> 0 | G30: =SUM(G5:G29) -> 0 | H30: =SUM(H5:H29) -> 0
A32: تنظيم كننده: | C32: حسابرس اعزامي: سعید حقانی | E32: رايزن فرهنگي: آقای اسماعیل زاده
A43: رايزني فرهنگي ج.ا.ايران در::ترکمنستان | F43: کد: 911321411
A44: از تاریخ 1391/7/28 لغایت 91/12/28 | F44: کد:9113214159
A45: هزينه جاري:حقوق، بازخريدي و...كاركنان بومي | F45: نرخ تسعير: | G45: =تسعير!E34 -> 3.6889904
A46: رديف | B46: تارخ سند | C46: شرح | D46: سند | E46: ارز محل | F46: معادل به يورو | G46: يورو | H46: جمع به يورو
A47: 1 | B47: 91/7/30 | C47: لیست پرداخت حقوق کارکنان در مهر ماه 91 | D47: 1 | F47: =E47/G3 -> 0 | G47: 2917 | H47: =G47+F47 -> 2917
A48: 2 | B48: 91/8/30 | C48: لیست پرداخت حقوق کارکنان در آبان ماه 91 | D48: 1 | F48: =E48/G3 -> 0 | G48: 2917 | H48: =G48+F48 -> 2917
A49: 3 | B49: 91/9/30 | C49: لیست پرداخت حقوق کارکنان در آذر ماه 91 | D49: 1 | F49: =E49/G3 -> 0 | G49: 2617 | H49: =G49+F49 -> 2617
A50: 4 | B50: 91/10/30 | C50: لیست پرداخت حقوق کارکنان در دی ماه 91 | D50: 1 | F50: =E50/G3 -> 0 | G50: 2617 | H50: =G50+F50 -> 2617
A51: 5 | B51: 91/11/30 | C51: لیست پرداخت حقوق کارکنان در بهمن ماه 91 | D51: 1 | F51: =E51/G3 -> 0 | G51: 2617 | H51: =G51+F51 -> 2617
...

Sheet ريز فرهنگي
A1: رايزني فرهنگي ج.ا.ايران در:ترکمنستان | J1: هزينه يك:برگزاري جشن نوروز
A2: از تاریخ 1391/7/28 لغایت 91/12/28 | J2: هزينه دو:انتشار 4 شماره از نشريه دوره اي خاوران
A3: هزينه فرهنگي يك: برگزاري جشن نوروز | F3: نرخ تسعير: | G3: =تسعير!E34 -> 3.6889904 | J3: هزينه سه: تعمیر و تجهیز مساجد
A4: رديف | B4: تارخ سند | C4: شرح | D4: سند | E4: ارز محل | F4: معادل به يورو | G4: يورو | H4: جمع به يورو | J4: هزينه چهار:برگزاری همایش امام رضاع
A5: 1 | F5: =E5/G3 -> 0 | H5: =G5+F5 -> 0 | J5: هزينه پنج:ترجمه و انتشار کتابي در باره امام رضا (ع)
A6: 2 | F6: =E6/G3 -> 0 | H6: =G6+F6 -> 0 | J6: هزينه شش:ترجمه وانتشار نهج البلاغه
A7: 3 | F7: =E7/G3 -> 0 | H7: =G7+F7 -> 0 | J7: هزينه هفت:حمايت از فعاليتهاي ديني وتبليغي
A8: 4 | F8: =E8/G3 -> 0 | H8: =G8+F8 -> 0 | J8: هزينه هشت:حمايت از خادمين زبان و ادبيات فارسي
A9: 5 | F9: =E9/G3 -> 0 | H9: =G9+F9 -> 0 | J9: هزينه نه:برگزاري 4 دوره (ترم) آموزش زبان فارسي
A10: 6 | F10: =E10/G3 -> 0 | H10: =G10+F10 -> 0 | J10: هزينه ده:برگزاري مراسم و مناسبت هاي ديني و مذهبي
A11: 7 | F11: =E11/G3 -> 0 | H11: =G11+F11 -> 0
A12: 8 | F12: =E12/G3 -> 0 | H12: =G12+F12 -> 0
A13: 9 | F13: =E13/G3 -> 0 | H13: =G13+F13 -> 0
A14: 10 | F14: =E14/G3 -> 0 | H14: =G14+F14 -> 0
A15: 11 | F15: =E15/G3 -> 0 | H15: =G15+F15 -> 0
A16: 12 | F16: =E16/G3 -> 0 | H16: =G16+F16 -> 0
A17: 13 | F17: =E17/G3 -> 0 | H17: =G17+F17 -> 0
A18: 14 | F18: =E18/G3 -> 0 | H18: =G18+F18 -> 0
A19: 15 | F19: =E19/G3 -> 0 | H19: =G19+F19 -> 0
A20: 16 | F20: =E20/G3 -> 0 | H20: =G20+F20 -> 0
A21: 17 | F21: =E21/G3 -> 0 | H21: =G21+F21 -> 0
A22: 18 | F22: =E22/G3 -> 0 | H22: =G22+F22 -> 0
A23: 19 | F23: =E23/G3 -> 0 | H23: =G23+F23 -> 0
A24: 20 | F24: =E24/G3 -> 0 | H24: =G24+F24 -> 0
A25: 21 | F25: =E25/G3 -> 0 | H25: =G25+F25 -> 0
A26: 22 | F26: =E26/G3 -> 0 | H26: =G26+F26 -> 0
A27: 23 | F27: =E27/G3 -> 0 | H27: =G27+F27 -> 0
A28: 24 | F28: =E28/G3 -> 0 | H28: =G28+F28 -> 0
A29: 25 | F29: =E29/G3 -> 0 | H29: =G29+F29 -> 0
A30: جمع كل | E30: =SUM(E5:E29) -> 0 | F30: =E30/G3 -> 0 | G30: =SUM(G5:G29) -> 0 | H30: =SUM(H5:H29) -> 0
A32: تنظيم كننده: | C32: حسابرس اعزامي: | E32: رايزن فرهنگي:
A43: رايزني فرهنگي ج.ا.ايران در:ترکمنستان
A44: از تاریخ 1391/7/28 لغایت 91/12/28 | F44: کد:9113214125
A45: هزينه فرهنگي دو: انتشار 4 شماره از نشريه دوره اي خاوران | F45: نرخ تسعير: | G45: =تسعير!E34 -> 3.6889904
A46: رديف | B46: تارخ سند | C46: شرح | D46: سند | E46: ارز محل | F46: معادل به يورو | G46: يورو | H46: جمع به يورو
A47: 1 | B47: 92/12/20 | C47: ترجمه مقالات مجله خاوران - خ نورنبات | D47: 4 | E47: 1970 | F47: =E47/G3 -> 534.02145 | H47: =G47+F47 -> 534.02145
A48: 2 | B48: 91/12/25 | C48: خرید و تکثیر سی دی خاوران | D48: 1 | E48: 70 | F48: =E48/G3 -> 18.975381 | H48: =G48+F48 -> 18.975381
A49: 3 | F49: =E49/G3 -> 0 | H49: =G49+F49 -> 0
A50: 4 | F50: =E50/G3 -> 0 | H50: =G50+F50 -> 0
A51: 5 | F51: =E51/G3 -> 0 | H51: =G51+F51 -> 0
...

Sheet حقوق مرکزی ها
A1: هزینه حقوق: پرسنلی اعزامی از مرکز
A2: نمایندگی ج.ا.ایران در ترکمنستان
A3: از تاریخ 1391/7/28 لغایت 91/12/28 | G3: ارقام : یورو
A5: ردیف | B5: نام و نام خانوادگی | C5: رسول اسماعیل زاده | D5: نعمتی زاده | E5: اضافه کار نعمتی زاده | F5: میرمحمدی | H5: توضیحات
A6: 1 | B6: فروردین
A7: 2 | B7: اردیبهشت
A8: 3 | B8: خرداد
A9: 4 | B9: تیر
A10: 5 | B10: مرداد | E10: 483
A11: 6 | B11: شهریور | E11: 0
A12: 7 | B12: مهر | C12: 18000 | D12: 7800 | E12: 338 | F12: 13788
A13: 8 | B13: آبان | D13: 0 | F13: 0
A14: 9 | B14: آذر | C14: 11186 | D14: 0 | F14: 0
A15: 10 | B15: دی | C15: 4623 | D15: 7800 | F15: 13788
A16: 11 | B16: بهمن | C16: 1203 | F16: 0
A17: 12 | B17: اسفند | F17: 0 | H17: برگ سند 16
A18: جمع پرداخت شده به تفکیک افراد | C18: =SUM(C6:C17) -> 35012 | D18: =SUM(D6:D17) -> 15600 | E18: =SUM(E6:E17) -> 821 | F18: =SUM(F6:F17) -> 27576 | G18: =SUM(G6:G17) -> 0
A19: جمع کل : | C19: =G18+F18+E18+D18+C18 -> 79009
B22: تنظیم کننده : سعید حقانی | F22: رایزنی فرهنگی ج.ا.ایران در ترکمنستان :
F23: رسول اسماعیل زاده

Sheet روكش جاري و فرهنگي
A1: ليست كلي هزينه هاي جاري رايزني فرهنگي ج.ا.ايران در ترکمنستان -عشق آباد
A2: از تاریخ 1391/7/28 لغایت 91/12/28
A4: رديف | B4: كد برنامه | C4: عنوان برنامه | D4: ارز محل | E4: يورو | F4: جمع به يورو
A5: 1 | C5: هزينه بانكي | D5: ='ريز جاري'!E30 -> 0 | E5: ='ريز جاري'!G30 -> 0 | F5: =D5/تسعير!E34+E5 -> 0
A6: 2 | B6: 911321411 9113214159 | C6: هزينه:حقوق، بازخريدي و...كاركنان بومي | D6: ='ريز جاري'!E72 -> 0 | E6: ='ريز جاري'!G72 -> 28570 | F6: =D6/تسعير!E34+E6 -> 28570
A7: 3 | B7: 911321417 | C7: هزينه:هزينه آب برق گاز و ساير سوخت ها | D7: ='ريز جاري'!E156 -> 798 | E7: ='ريز جاري'!G156 -> 0 | F7: =D7/تسعير!E34+E7 -> 216.31935
A8: 4 | B8: 911321416 | C8: هزينه:تعمير و نگهداري خودرو | D8: ='ريز جاري'!E198 -> 150 | E8: ='ريز جاري'!G198 -> 0 | F8: =D8/تسعير!E34+E8 -> 40.661531
A9: 5 | C9: ترميم و نگهداري جزئي ساختمان | D9: ='ريز جاري'!E240 -> 0 | E9: ='ريز جاري'!G240 -> 0 | F9: =D9/تسعير!E34+E9 -> 0
A10: 6 | C10: حمل و نقل و ارتباطات | D10: ='ريز جاري'!E282 -> 0 | E10: ='ريز جاري'!G282 -> 0 | F10: =D10/تسعير!E34+E10 -> 0
A11: 7 | B11: 911321419 | C11: تلفن ، فاكس و اينترنت | D11: ='ريز جاري'!E324 -> 14009 | E11: ='ريز جاري'!G324 -> 0 | F11: =D11/تسعير!E34+E11 -> 3797.516
A12: 8 | B12: 9113214111 | C12: هزينه: کمک هزینه تحصیلی فرزندان | D12: ='ريز جاري'!E366 -> 2642.6 | E12: ='ريز جاري'!G366 -> 0 | F12: =D12/تسعير!E34+E12 -> 716.34775
A13: 9 | B13: 911321412 | C13: كمك هزينه درمان و بيمه كاركنان | D13: ='ريز جاري'!E408 -> 1033 | E13: ='ريز جاري'!G408 -> 0 | F13: =D13/تسعير!E34+E13 -> 280.02241
A14: 10 | C14: هزينه هاي خارج از مصوب و تخصيص | D14: ='ريز جاري'!E450 -> 0 | E14: ='ريز جاري'!G450 -> 0 | F14: =D14/تسعير!E34+E14 -> 0
A15: 11 | C15: هزينه هاي پيش بيني نشده | D15: ='ريز جاري'!E492 -> 0 | E15: ='ريز جاري'!G492 -> 0 | F15: =D15/تسعير!E34+E15 -> 0
A16: 12 | B16: 911321413 | C16: هزينه:خريد اقلام مصرفي و پذیرائی | D16: ='ريز جاري'!E114 -> 4248 | E16: ='ريز جاري'!G114 -> 0 | F16: =D16/تسعير!E34+E16 -> 1151.5346
A17: 13 | C17: هزينه حقوق كاركنان اعزامي از مركز | E17: 79009 | F17: =D17/تسعير!E34+E17 -> 79009
A18: 14 | F18: =D18/تسعير!E34+E18 -> 0
A19: 15 | F19: =D19/تسعير!E34+E19 -> 0
A20: 16 | F20: =D20/تسعير!E34+E20 -> 0
A21: 17 | F21: =D21/تسعير!E34+E21 -> 0
A22: 18 | F22: =D22/تسعير!E34+E22 -> 0
A23: 19 | F23: =D23/تسعير!E34+E23 -> 0
A24: 20 | F24: =D24/تسعير!E34+E24 -> 0
A25: 21 | F25: =D25/تسعير!E34+E25 -> 0
A26: 22 | F26: =D26/تسعير!E34+E26 -> 0
A27: 23 | F27: =D27/تسعير!E34+E27 -> 0
A28: 24 | F28: =D28/تسعير!E34+E28 -> 0
A29: 25 | F29: =D29/تسعير!E34+E29 -> 0
A30: 26 | F30: =D30/تسعير!E34+E30 -> 0
A31: 27 | F31: =D31/تسعير!E34+E31 -> 0
A32: 28 | F32: =D32/تسعير!E34+E32 -> 0
A33: 29 | F33: =D33/تسعير!E34+E33 -> 0
A34: 30 | F34: =D34/تسعير!E34+E34 -> 0
A35: جمع هزينه هاي جاري | D35: =SUM(D5:D34) -> 22880.6 | E35: =SUM(E5:E34) -> 107579 | F35: =SUM(F5:F34) -> 113781.4
A37: تنظيم كننده: | C37: حسابرس اعزامي: سعید حقانی | E37: رايزني فرهنگي ج.ا.ا: ترکمنستان
A47: ليست كلي هزينه هاي فرهنگي رايزني فرهنگي ج.ا.ايران در ترکمنستان -عشق آباد
A48: از تاریخ 1391/7/28 لغایت 91/12/28
A50: رديف | B50: كد برنامه | C50: عنوان برنامه | D50: ارز محل | E50: يورو | F50: جمع به يورو
A51: 1 | C51: برگزاري جشن نوروز | D51: ='ريز فرهنگي'!E30 -> 0 | E51: ='ريز فرهنگي'!G30 -> 0 | F51: =D51/تسعير!E34+E51 -> 0
A52: 2 | B52: 9113214125 | C52: انتشار 4 شماره از نشريه دوره اي خاوران | D52: ='ريز فرهنگي'!E72 -> 2040 | E52: ='ريز فرهنگي'!G72 -> 0 | F52: =D52/تسعير!E34+E52 -> 552.99683
...

Sheet تراز يوروئي و ارزمحل
A2: نمايندگي فرهنگي سفارت ج.ا.ايران در ترکمنستان
A3: تراز عمليات مالي حساب هاي يوروئي از تاريخ 1391/7/28 لغايت 91/12/28 ارقام به: يورو
A4: شرح حساب | B4: گردش عمليات مالي | D4: مانده نهايي حساب
B6: بدهكار | C6: بستانكار | D6: بدهكار | E6: بستانكار
A7: بانك:
A8: حساب(جاري1) يورويي به شماره
A9: حساب(جاري2) يورويي به شماره
A10: تنخواه گردان پرداختي:
A11: موجودي صندوق | D11: 76843.5
A12: علي الحساب ها:
A13: يك:علي الحساب جک امانی آقای ناصری | E13: 16058
A14: دو: تعهدات پرداخت نشده(چک آقای ناصری | D14: 16058
A15: سه: پيش پرداخت
A16: وام كاركنان محلي(بدهكار)
A17: حساب سفارت(مانده حساب رايزني نزد سفارت)
A18: حساب تسعير يورو به ارز محل | D18: =تسعير!D34 -> 20342.46
A19: هزينه ها:
A20: هزينه هاي جاري | D20: ='روكش جاري و فرهنگي'!E35-'روكش جاري و فرهنگي'!F17 -> 28570
A21: هزينه هاي فرهنگي | D21: ='روكش جاري و فرهنگي'!E81 -> 500
A22: هزينه حقوق كاركنان اعزامي از مركز | D22: ='روكش جاري و فرهنگي'!F17 -> 79009
A23: هزينه(1)
A24: هزينه(2)
A25: حساب دريافتي از سازمان بابت بودجه برنامه اي:
A26: بابت بودجه برنامه اي سال جاري | E26: 163000
A27: بابت(1)علي الحساب دريافتي از مركز...
A28: حساب وجوه مصرف نشده سنوات قبل
A29: مانده موجودي نقل از دوره قبل(صورتجلسه) | E29: 42265
A30: دريافتي بابت درآمد
A31: جمع كل: | B31: =SUM(B7:B30) -> 0 | C31: =SUM(C7:C30) -> 0 | D31: =SUM(D7:D30) -> 221322.96 | E31: =SUM(E7:E30) -> 221323
A33: بدين وسيله صحت ارقام در ترازنامه نمايندگي به شرح فوق از تاريخ 91/7/28 لغايت 91/12/28 مورد تأئيد است.
A35: حسابرس اعزامي: سعید حقانی | C35: رايزني فرهنگي ج.ا.ايران در ترکمنستان
A43: نمايندگي فرهنگي سفارت ج.ا.ايران در ترکمنستان
A44: تراز عمليات مالي حساب هاي ارز محل از تاريخ 1391/7/28 لغايت 1391/12/28 ارقام به :ارز محل
D45: نرخ ميانگين تسعير: | E45: =تسعير!E34 -> 3.6889904
A46: شرح حساب | B46: گردش عمليات مالي | D46: مانده نهايي حساب
B48: بدهكار | C48: بستانكار | D48: بدهكار | E48: بستانكار
A49: بانك:
A50: حساب(جاري1) ارز محل به شماره
A51: حساب(جاري2) ارز محل به شماره
A52: تنخواه گردان پرداختي:
...

Sheet تراز تلفيقي
A1: نمايندگي فرهنگي سفارت ج.ا.ايران در ترکمنستان
A2: تراز عمليات تلفيقي (حساب ارز محل و يورو)
A3: از تاریخ 1391/7/28 لغایت 91/12/28 نرخ ميانگين تسعير: | E3: =تسعير!E34 -> 3.6889904
A4: شرح حساب | B4: حساب هاي يوروئي | D4: معادل يورو حساب هاي ارز محل | F4: مانده نهايي به يورو
B5: بدهكار | C5: بستانكار | D5: بدهكار | E5: بستانكار | F5: بدهكار | G5: بستانكار
A6: بانك:
A7: حساب يوروئي(1) به شماره | B7: ='تراز يوروئي و ارزمحل'!D8 -> 0 | F7: =B7 -> 0
A8: حساب يوروئي(2) به شماره | B8: ='تراز يوروئي و ارزمحل'!D9 -> 0 | F8: =B8 -> 0
A9: حساب ارز محل(1) به شماره | D9: ='تراز يوروئي و ارزمحل'!D50/تسعير!E34 -> 0 | F9: =D9 -> 0
A10: حساب ارز محل(2) به شماره | D10: ='تراز يوروئي و ارزمحل'!D51/تسعير!E34 -> 0 | F10: =D10 -> 0
A11: تنخواه گردان پرداخت:
A12: موجودي صندوق | B12: ='تراز يوروئي و ارزمحل'!D11 -> 76843.5 | C12: ='تراز يوروئي و ارزمحل'!E11 -> 0 | D12: ='تراز يوروئي و ارزمحل'!D53/تسعير!E34 -> 0 | E12: ='تراز يوروئي و ارزمحل'!E53/'تراز يوروئي و ارزمحل'!E45 -> 0 | F12: =D12+B12-E12-C12 -> 76843.5
A13: علي الحساب ها:
A14: يك:علي الحساب جک امانی آقای ناصری | C14: ='تراز يوروئي و ارزمحل'!E13 -> 16058 | E14: ='تراز يوروئي و ارزمحل'!E55/تسعير!E34 -> 0 | G14: =E14+C14 -> 16058
A15: دو: تعهدات پرداخت نشده(چک آقای ناصری | B15: ='تراز يوروئي و ارزمحل'!D14 -> 16058 | D15: ='تراز يوروئي و ارزمحل'!D56/تسعير!E34 -> 0 | F15: =D15+B15 -> 16058
A16: علي الحساب سه | B16: ='تراز يوروئي و ارزمحل'!D15 -> 0 | D16: ='تراز يوروئي و ارزمحل'!D57/تسعير!E34 -> 0 | F16: =D16+B16 -> 0
A17: وام كاركنان محلي | B17: ='تراز يوروئي و ارزمحل'!D16 -> 0 | D17: ='تراز يوروئي و ارزمحل'!D58/تسعير!E34 -> 0 | F17: =D17+B17 -> 0
A18: حساب سفارت | B18: ='تراز يوروئي و ارزمحل'!D17 -> 0 | D18: ='تراز يوروئي و ارزمحل'!D59/تسعير!E34 -> 0 | F18: =D18+B18 -> 0
A19: حساب تسعير يورو به ارز محل | B19: ='تراز يوروئي و ارزمحل'!D18 -> 20342.46 | F19: =B19 -> 20342.46
A20: حساب دريافتي ناشي از تسعير يورو به ارز محل | E20: ='تراز يوروئي و ارزمحل'!E67/تسعير!E34 -> 20342.46 | G20: =E20 -> 20342.46
A21: هزينه ها:
A22: هزينه هاي جاري | B22: ='تراز يوروئي و ارزمحل'!D20 -> 28570 | D22: ='تراز يوروئي و ارزمحل'!D61/تسعير!E34 -> 6202.4016 | F22: =D22+B22 -> 34772.402
A23: هزينه هاي فرهنگي | B23: ='تراز يوروئي و ارزمحل'!D21 -> 500 | D23: ='تراز يوروئي و ارزمحل'!D62/تسعير!E34 -> 14140.058 | F23: =D23+B23 -> 14640.058
A24: هزينه حقوق كاركنان اعزامي از مركز | B24: ='تراز يوروئي و ارزمحل'!D22 -> 79009 | F24: =B24 -> 79009
A25: هزينه يك | B25: ='تراز يوروئي و ارزمحل'!D23 -> 0 | D25: ='تراز يوروئي و ارزمحل'!D63/تسعير!E34 -> 0 | F25: =D25+B25 -> 0
A26: هزينه دو | B26: ='تراز يوروئي و ارزمحل'!D24 -> 0 | D26: ='تراز يوروئي و ارزمحل'!D64/تسعير!E34 -> 0 | F26: =D26+B26 -> 0
A27: هزينه خريد خودرو | F27: =D27+B27 -> 0
A28: هزينه هاي واخواهي شده | F28: =D28+B28 -> 0
A29: حساب دريافتي از سازمان بابت بودجه برنامه اي
A30: بابت بودجه برنامه اي سال جاري | C30: ='تراز يوروئي و ارزمحل'!E26 -> 163000 | G30: =C30 -> 163000
A31: بابت(1) بودجه ساير ادارات | C31: ='تراز يوروئي و ارزمحل'!E27 -> 0 | G31: =C31 -> 0
A32: حساب وجوه مصرف نشده سنوات قبل
A33: مانده موجودي نقل از دوره قبل(صورتجلسه) | C33: ='تراز يوروئي و ارزمحل'!E29 -> 42265 | E33: ='تراز يوروئي و ارزمحل'!E66/تسعير!E34 -> 0 | G33: =E33+C33 -> 42265
A34: دريافتي بابت درآمد | C34: ='تراز يوروئي و ارزمحل'!E30 -> 0 | E34: ='تراز يوروئي و ارزمحل'!E68/تسعير!E34 -> 0 | G34: =E34+C34 -> 0
A35: جمع كل | B35: =SUM(B6:B34) -> 221322.96 | C35: =SUM(C6:C34) -> 221323 | D35: =SUM(D6:D34) -> 20342.46 | E35: =SUM(E6:E34) -> 20342.46 | F35: =SUM(F6:F34) -> 241665.42 | G35: =SUM(G6:G34) -> 241665.46
A36: بدين وسيله صحت ارقام در ترازنامه نمايندگي به شرح فوق از تاريخ 1391/7/28لغايت 91/12/28 با نرخ ميانگين تسعير: 3.689
A37: برابر با يك يورو مورد تأئيد است.
A38: حسابرس اعزامي: سعید حقانی | D38: رايزني فرهنگي ج.ا.ايران در ترکمنستان

Sheet فهرست وجوه ارسالي
A2: نمايندگي فرهنگي سفارت ج.ا.ايران در ترکمنستان
A3: فهرست وجوه ارسالي از سازمان فرهنگ و ارتباطات اسلامي سال 1391
G4: ارقام: به يورو
A5: رديف | B5: شرح برنامه | C5: شماره سند | D5: شماره حواله | E5: تاريخ حواله | F5: بودجه ارسالي | G5: بودجه واريز شده به حساب | H5: كارمزد بانكي
A6: 1 | B6: علی الحساب جاری و فرهنگی 91 | D6: 84/26155 | E6: 91/7/4 | F6: 5000 | G6: 5000 | H6: نقدی دریافت
A7: 2 | B7: جاری و فرهنگی | D7: 84/26330 | E7: 91/7/18 | F7: 19156 | G7: 19156 | H7: نقدی دریافت
A8: 3 | B8: حقوق و مزایای آقای میر محمدی | D8: 26330 | E8: 91/7/18 | F8: 26478 | G8: 26478 | H8: نقدی دریافت
A9: 4 | B9: حقوق و مزایای آقای اسماعیل زاده | D9: 26330 | E9: 91/7/18 | F9: 18000 | G9: 18000 | H9: نقدی دریافت
A10: 5 | B10: حقوق و مزایای آقای نعمتی زاده | D10: 26330 | E10: 91/7/18 | F10: 6366 | G10: 6366 | H10: نقدی دریافت
A11: 6 | B11: حقوق نعمتی زاده | C11: 657 | D11: 84/26679 | E11: 91/11/14 | F11: 8814 | G11: 8814 | H11: نقدی دریافت
A12: 7 | B12: حقوق اسماعیل زاده | C12: 657 | D12: 84/26679 | E12: 91/11/14 | F12: 11186 | G12: 11186 | H12: نقدی دریافت
A13: 8 | B13: حقوق میرمحمدی | C13: 757 | D13: 84/26827 | E13: 91/12/13 | F13: 8826 | G13: 8826 | H13: نقدی دریافت
A14: 9 | B14: حقوق اسماعیل زاده | C14: 757 | D14: 84/26827 | E14: 91/12/13 | F14: 4623 | G14: 4623 | H14: نقدی دریافت
A15: 10 | B15: حقوق نعمتی زاده | C15: 757 | D15: 84/26827 | E15: 91/12/13 | F15: 2938 | G15: 2938 | H15: نقدی دریافت
A16: 11 | B16: جاری و فرهنگی | C16: 757 | D16: 84/26827 | E16: 91/12/13 | F16: 4613 | G16: 4613 | H16: نقدی دریافت
A17: 12 | B17: حقوق میرمحمدی | C17: 838 | D17: 84/26949 | E17: 92/1/10 | F17: 19848 | G17: 19848 | H17: نقدی دریافت
A18: 13 | B18: حقوق اسماعیل زاده | C18: 838 | D18: 84/26949 | E18: 92/1/10 | F18: 1203 | G18: 1203 | H18: نقدی دریافت
A19: 14 | B19: حقوق نعمتی زاده | C19: 838 | D19: 84/26949 | E19: 92/1/10 | F19: 5876 | G19: 5876 | H19: نقدی دریافت
A20: 15 | B20: بازخریدی پرویز میرزآاف | C20: 838 | D20: 84/26949 | E20: 92/1/10 | F20: 3300 | G20: 3300 | H20: نقدی دریافت
A21: 16 | B21: بازخریدی رشید عباس اف | C21: 838 | D21: 84/26949 | E21: 92/1/10 | F21: 2053 | G21: 2053 | H21: نقدی دریافت
A22: 17 | B22: بازخریدی فرهاد سقلی | C22: 838 | D22: 84/26949 | E22: 92/1/10 | F22: 9720 | G22: 9720 | H22: نقدی دریافت
A23: 18 | B23: جشن نوروز | F23: 5000 | G23: 5000 | H23: نقدی دریافت
A24: جمع كل | F24: =SUM(F6:F23) -> 163000 | G24: =SUM(G6:G23) -> 163000 | H24: =SUM(H11:H23) -> 0
A25: بدينوسيله گواهي مي شود مبالغ فوق الذكر بابت بودجه جاري و فرهنگي تحویلی به نمايندگي فرهنگی ج .ا.ایران در ترکمنستان
A26: دریافت و مورد تاييد است.
A28: حسابرس اعزامي از مركز: سعید حقانی | F28: رايزن فرهنگي ج.ا. ايران در ترکمستان
G29: آقای اسماعیل زاده

Sheet هزينه و انحراف 2
A1: صورت خلاصه هزینه های جاری نمایندگی فرهنگی جمهوری اسلامی ایران در تركمنستان از تاریخ 1391/07/28لغایت 1391/12/29
A4: ردیف | B4: کد برنامه | C4: عنوان هزینه | D4: بودجه | E4: هزینه | F4: معادل | G4: هزینه | H4: جمع عملکرد | I4: بودجه | J4: انحراف | K4: تعداد سند به برگ
D5: مصوب | E5: به ارز محل | F5: یوروئی هزینه | G5: به یورو | H5: هزینه | I5: تخصیص | J5: هزینه
A6: 1 | B6: 911321411 9113214159 | C6: حقوق کارکنان محلی و بازخریدی رایزنی | F6: =E6/E28 -> 0 | G6: 28570 | H6: =F6+G6 -> 28570 | I6: 49829 | J6: =I6-H6 -> 21259 | K6: 44
A7: 2 | B7: 911321412 | C7: کمک هزینه درمان وبیمه کارکنان | E7: 1033 | F7: =E7/E28 -> 280.02241 | H7: =F7+G7 -> 280.02241 | I7: 1000 | J7: =I7-H7 -> 719.97759 | K7: 14
A8: 3 | B8: 9113214111 | C8: کمک هزینه تحصیلی فرزندان کارکنان اعزامی مرکز | E8: 2642.6 | F8: =E8/E28 -> 716.34775 | H8: =F8+G8 -> 716.34775 | I8: 1000 | J8: =I8-H8 -> 283.65225 | K8: 3
A9: 4 | B9: 911321416 | C9: هزینه های تعمير و نگهداري خودرو | E9: 150 | F9: =E9/E28 -> 40.661531 | H9: =F9+G9 -> 40.661531 | I9: 2000 | J9: =I9-H9 -> 1959.3385 | K9: 2
A10: 5 | B10: 911321417 | C10: هزينه آب؛برق؛گاز؛وسایر سوختها | E10: 798 | F10: =E10/E28 -> 216.31935 | H10: =F10+G10 -> 216.31935 | I10: 1000 | J10: =I10-H10 -> 783.68065 | K10: 26
A11: 6 | B11: 911321419 | C11: هزینه تلفن ؛ فکس ؛ واينترنت | E11: 14009 | F11: =E11/E28 -> 3797.516 | H11: =F11+G11 -> 3797.516 | I11: 7000 | J11: =I11-H11 -> 3202.484 | K11: 27
A12: 7 | B12: 911321413 | C12: خرید اقلام مصرفی و پذیرائی | E12: 4248 | F12: =E12/E28 -> 1151.5346 | H12: =F12+G12 -> 1151.5346 | I12: 2000 | J12: =I12-H12 -> 848.46543 | K12: 39
A13: 8 | F13: =E13/E28 -> 0 | H13: =G13+F13 -> 0 | J13: =I13-H13 -> 0
A14: 9 | F14: =E14/E28 -> 0 | H14: =G14+F14 -> 0 | J14: =I14-H14 -> 0
A15: 10 | F15: =E15/E28 -> 0 | H15: =G15+F15 -> 0 | J15: =I15-H15 -> 0
A16: 11 | F16: =E16/E28 -> 0 | H16: =G16+F16 -> 0 | J16: =I16-H16 -> 0
A17: 12 | F17: =E17/E28 -> 0 | H17: =G17+F17 -> 0 | J17: =I17-H17 -> 0
A18: 13 | F18: =E18/E28 -> 0 | H18: =G18+F18 -> 0 | J18: =I18-H18 -> 0
A19: 14 | B19: 9113214110 | C19: حمل نقل و ارتباطات | F19: =E19/E28 -> 0 | H19: 0 | I19: 2000 | J19: =I19-H19 -> 2000
A20: 15 | B20: 911321418 | C20: هزینه های بانکی و پست | F20: =E20/E28 -> 0 | H20: =F20+G20 -> 0 | I20: 500 | J20: =I20-H20 -> 500
A21: 16 | B21: 911321414 | C21: هزینه های پیش بینی نشده در امور فرهنگی و جاری | F21: =E21/E28 -> 0 | H21: =F21+G21 -> 0 | I21: 2500 | J21: =I21-H21 -> 2500
A22: 17 | B22: 911321415 | C22: هزينه های تعمير و نگهداري اماكن و وسايل اداري | F22: =E22/E28 -> 0 | H22: =F22+G22 -> 0 | I22: 1000 | J22: =I22-H22 -> 1000
A23: 18 | B23: 9113214159 | C23: حقوق اعزامی از مرکز | F23: =E23/E28 -> 0 | G23: 79009 | H23: =F23+G23 -> 79009 | I23: 55152 | J23: =I23-H23 -> -23857 | K23: 14
A24: 19 | C24: علی الحساب حقوق کارکنان محلی | F24: =E24/E28 -> 0 | H24: =F24+G24 -> 0 | J24: =I24-H24 -> 0
A25: 20 | C25: هزینه اجاره ساختمان مرکز آموزش | F25: =E25/E28 -> 0 | H25: =F25+G25 -> 0 | J25: =I25-H25 -> 0
A26: 21 | C26: علی الحساب حقوق کارکنان اعزامی | F26: =E26/E28 -> 0 | H26: =F26+G26 -> 0 | J26: =I26-H26 -> 0
A27: جمع کل هزینه های جاری و حقوق | D27: =SUM(D6:D25) -> 0 | E27: =SUM(E6:E25) -> 22880.6 | F27: =SUM(F6:F25) -> 6202.4016 | G27: =SUM(G6:G25) -> 107579 | H27: =SUM(H6:H26) -> 113781.4 | I27: =SUM(I6:I25) -> 124981 | J27: =SUM(J6:J25) -> 11199.598 | K27: =SUM(K6:K26) -> 169
D28: تسعير: | E28: =تسعير!E34 -> 3.6889904 | G28: آقای اسماعیل زاده
C29: حسابرس اعزامي: سعید حقانی | G29: رایزن فرهنگی جمهوری اسلامی ایران در تركمنستان
A37: صورت خلاصه هزینه های فرهنگی نمایندگی فرهنگی جمهوری اسلامی ایران در تركمنستان از تاریخ 1391/07/28لغایت 1391/12/29
A40: ردیف | B40: کد برنامه | C40: عنوان هزینه | D40: بودجه | E40: هزینه | F40: معادل | G40: هزینه | H40: جمع عملکرد | I40: بودجه | J40: انحراف | K40: تعداد سند به برگ
D41: مصوب | E41: به ارز محل | F41: یوروئی هزینه | G41: به یورو | H41: هزینه | I41: تخصیص | J41: هزینه
A42: 1 | B42: 9113214122 | C42: برگزاری جشن نوروز | F42: =E42/E78 -> 0 | H42: =F42+G42 -> 0 | I42: 4000 | J42: =I42-H42 -> 4000
A43: 2 | B43: 9113214123 | C43: برگزاری مراسم مردمی سالگرد ارتحال امام ره | F43: =E43/E78 -> 0 | H43: =F43+G43 -> 0 | I43: 2000 | J43: =I43-H43 -> 2000
A44: 3 | B44: 9113214124 | C44: برگزاری مراسم ویژه برزگداشت نیمه شعبان | F44: =E44/E78 -> 0 | H44: =F44+G44 -> 0 | I44: 2000 | J44: =I44-H44 -> 2000
A45: 4 | B45: 9113214125 | C45: انتشار 4 شماره از نشریه دوره ای خاوران | E45: 2040 | F45: =E45/E78 -> 552.99683 | H45: =F45+G45 -> 552.99683 | I45: 6800 | J45: =I45-H45 -> 6247.0032 | K45: 5
A46: 5 | B46: 9113214126 | C46: برکزاری مناسبتهای دینی و مذهبی(رمضان محرم ولادتها و وفاتهاو... | E46: 10078 | F46: =E46/E78 -> 2731.9128 | H46: =F46+G46 -> 2731.9128 | I46: 5000 | J46: =I46-H46 -> 2268.0872 | K46: 40
A47: 6 | B47: 9113214127 | C47: برگزاری هفته فرهنگی | F47: =E47/E78 -> 0 | H47: =F47+G47 -> 0 | I47: 4000 | J47: =I47-H47 -> 4000
A48: 7 | B48: 9113214128 | C48: برگزاری روزهای دوستی کودکان و نوجوانان ایران و ترکمنستان | F48: =E48/E78 -> 0 | H48: =F48+G48 -> 0 | I48: 2000 | J48: =I48-H48 -> 2000
A49: 8 | B49: 9113214129 | C49: برگزاری نمایشگاه قرآنی در ماه مبارک رمضان | F49: =E49/E78 -> 0 | H49: =G49+F49 -> 0 | I49: 1500 | J49: =I49-H49 -> 1500
A50: 9 | B50: 9113214130 | C50: برگزاري همايش امام رضا (ع) در مرو | E50: 400 | F50: =E50/E78 -> 108.43075 | H50: =G50+F50 -> 108.43075 | I50: 4000 | J50: =I50-H50 -> 3891.5692 | K50: 12
A51: 10 | B51: 9113214131 | C51: برگزاري مراسم مردمي روز قدس | F51: =E51/E78 -> 0 | H51: =G51+F51 -> 0 | I51: 2500 | J51: =I51-H51 -> 2500
...
